Workbook

Sheet 0-LIRE DABORD
A1: CLASSEUR — SESSIONS (heures) + CHANGEMENTS DE LAMES À PART + TRS
B4: DEUX FEUILLES DE SAISIE SÉPARÉES :
B6: FEUILLE 2 — SESSIONS DE SCIAGE :
B7: Tu écris les HEURES début et fin de chaque plage de sciage, plus l'observation.
B8: La durée se calcule seule (fin moins début). Chaque ligne est indépendante : changer de jour ne casse rien.
B9: L'observation dit ce qui s'est passé PENDANT la session :
B10: • ok = sciait normalement → compté en SCIAGE BON
B11: • sciage un côté / mauvaise épaisseur / rayures = sciait mal → SCIAGE DÉGRADÉ
B12: • zéro / panne = machine ARRÊTÉE pendant la session → ARRÊT
B14: FEUILLE 3 — CHANGEMENTS DE LAMES (séparée) :
B15: Tu écris les HEURES début et fin de chaque changement de lame. La durée se calcule seule.
B16: Plus besoin de deviner les trous : tu écris chaque changement directement ici.
B18: CE QU'ON A SUPPRIMÉ :
... B26: CONSEIL : commence par la BICOUPE, un poste complet.

Sheet 1-REF
A1: LISTES POUR MENUS (ne pas modifier)
A3: Observations session | C3: Machines | E3: Essences
A4: ok | C4: Schulte (scie de tête) | E4: Ayous
A5: sciage un côté | C5: Bicoupe | E5: Azobé
A6: mauvaise épaisseur | C6: Brenta (déligneuse) | E6: Bilinga
A7: rayures | C7: Dédoubleuse | E7: Iroko
A8: zéro | C8: Ébouteuse | E8: Movingui
A9: panne mécanique
A10: panne électrique

Sheet 2-SESSIONS SCIAGE
A1: SESSIONS DE SCIAGE (heures début/fin)
A2: QUOI REMPLIR (jaune) : Date, Équipe, Machine (menu), Heure début, Heure fin, Observation (menu).
A3: Heures en hh:mm. Durée auto (gère minuit). Retard relève = trou quand l'équipe change (auto). Changement de lame = feuille 3.
A4: Date | B4: Équipe | C4: Machine | D4: Heure début | E4: Heure fin | F4: Durée (min, auto) | G4: Observation | H4: Retard relève (min, auto) | I4: Date du quart (auto) | J4: Créneau (auto)
A5: 11/06 | B5: B | C5: Bicoupe | D5: 06:00 | E5: 08:00 | F5: =IF(OR(D5="",E5=""),"",(MOD(E5-D5,1))*1440) -> 120 | G5: ok | I5: =IF(OR(A5="",D5=""),"",IF(D5<TIME(6,0,0),A5-1,A5)) -> 11/06 | J5: =IF(D5="","",IF(D5<TIME(6,0,0),"Nuit",IF(D5<TIME(14,0,0),"Matin",IF(D5<TIME(22,0,0),"Après-midi","Nuit")))) -> Nuit
A6: 11/06 | B6: B | C6: Bicoupe | D6: 08:15 | E6: 09:00 | F6: =IF(OR(D6="",E6=""),"",(MOD(E6-D6,1))*1440) -> 45 | G6: ok | H6: =IF(OR(D6="",E5="",C6<>C5,B6=B5),"",(MOD(D6-E5,1))*1440) | I6: =IF(OR(A6="",D6=""),"",IF(D6<TIME(6,0,0),A6-1,A6)) -> 11/06 | J6: =IF(D6="","",IF(D6<TIME(6,0,0),"Nuit",IF(D6<TIME(14,0,0),"Matin",IF(D6<TIME(22,0,0),"Après-midi","Nuit")))) -> Nuit
A7: 11/06 | B7: B | C7: Bicoupe | D7: 09:00 | E7: 09:30 | F7: =IF(OR(D7="",E7=""),"",(MOD(E7-D7,1))*1440) -> 30 | G7: panne mécanique | H7: =IF(OR(D7="",E6="",C7<>C6,B7=B6),"",(MOD(D7-E6,1))*1440) | I7: =IF(OR(A7="",D7=""),"",IF(D7<TIME(6,0,0),A7-1,A7)) -> 11/06 | J7: =IF(D7="","",IF(D7<TIME(6,0,0),"Nuit",IF(D7<TIME(14,0,0),"Matin",IF(D7<TIME(22,0,0),"Après-midi","Nuit")))) -> Nuit
A8: 11/06 | B8: B | C8: Bicoupe | D8: 09:30 | E8: 11:00 | F8: =IF(OR(D8="",E8=""),"",(MOD(E8-D8,1))*1440) -> 90 | G8: sciage un côté | H8: =IF(OR(D8="",E7="",C8<>C7,B8=B7),"",(MOD(D8-E7,1))*1440) | I8: =IF(OR(A8="",D8=""),"",IF(D8<TIME(6,0,0),A8-1,A8)) -> 11/06 | J8: =IF(D8="","",IF(D8<TIME(6,0,0),"Nuit",IF(D8<TIME(14,0,0),"Matin",IF(D8<TIME(22,0,0),"Après-midi","Nuit")))) -> Nuit
A9: 11/06 | B9: B | C9: Bicoupe | D9: 11:15 | E9: 13:40 | F9: =IF(OR(D9="",E9=""),"",(MOD(E9-D9,1))*1440) -> 145 | G9: ok | H9: =IF(OR(D9="",E8="",C9<>C8,B9=B8),"",(MOD(D9-E8,1))*1440) | I9: =IF(OR(A9="",D9=""),"",IF(D9<TIME(6,0,0),A9-1,A9)) -> 11/06 | J9: =IF(D9="","",IF(D9<TIME(6,0,0),"Nuit",IF(D9<TIME(14,0,0),"Matin",IF(D9<TIME(22,0,0),"Après-midi","Nuit")))) -> Nuit
A10: 11/06 | B10: B | C10: Bicoupe | D10: 13:40 | E10: 14:00 | F10: =IF(OR(D10="",E10=""),"",(MOD(E10-D10,1))*1440) -> 20 | G10: zéro | H10: =IF(OR(D10="",E9="",C10<>C9,B10=B9),"",(MOD(D10-E9,1))*1440) | I10: =IF(OR(A10="",D10=""),"",IF(D10<TIME(6,0,0),A10-1,A10)) -> 11/06 | J10: =IF(D10="","",IF(D10<TIME(6,0,0),"Nuit",IF(D10<TIME(14,0,0),"Matin",IF(D10<TIME(22,0,0),"Après-midi","Nuit")))) -> Nuit
F11: =IF(OR(D11="",E11=""),"",(MOD(E11-D11,1))*1440) | G11: ↑ exemple, tu peux effacer | H11: =IF(OR(D11="",E10="",C11<>C10,B11=B10),"",(MOD(D11-E10,1))*1440) | I11: =IF(OR(A11="",D11=""),"",IF(D11<TIME(6,0,0),A11-1,A11)) | J11: =IF(D11="","",IF(D11<TIME(6,0,0),"Nuit",IF(D11<TIME(14,0,0),"Matin",IF(D11<TIME(22,0,0),"Après-midi","Nuit"))))
A12: 46147 | B12: B | C12: Bicoupe | D12: 0.58333333 | E12: 0.60625 | F12: =IF(OR(D12="",E12=""),"",(MOD(E12-D12,1))*1440) -> 33 | G12: zéro | H12: =IF(OR(D12="",E11="",C12<>C11,B12=B11),"",(MOD(D12-E11,1))*1440) | I12: =IF(OR(A12="",D12=""),"",IF(D12<TIME(6,0,0),A12-1,A12)) -> 05/05 | J12: =IF(D12="","",IF(D12<TIME(6,0,0),"Nuit",IF(D12<TIME(14,0,0),"Matin",IF(D12<TIME(22,0,0),"Après-midi","Nuit")))) -> Après-midi
A13: 46147 | B13: B | C13: Bicoupe | D13: 0.60625 | E13: 0.67291667 | F13: =IF(OR(D13="",E13=""),"",(MOD(E13-D13,1))*1440) -> 96 | G13: ok | H13: =IF(OR(D13="",E12="",C13<>C12,B13=B12),"",(MOD(D13-E12,1))*1440) | I13: =IF(OR(A13="",D13=""),"",IF(D13<TIME(6,0,0),A13-1,A13)) -> 05/05 | J13: =IF(D13="","",IF(D13<TIME(6,0,0),"Nuit",IF(D13<TIME(14,0,0),"Matin",IF(D13<TIME(22,0,0),"Après-midi","Nuit")))) -> Après-midi
A14: 46147 | B14: B | C14: Bicoupe | D14: 0.68958333 | E14: 0.8125 | F14: =IF(OR(D14="",E14=""),"",(MOD(E14-D14,1))*1440) -> 177 | G14: ok | H14: =IF(OR(D14="",E13="",C14<>C13,B14=B13),"",(MOD(D14-E13,1))*1440) | I14: =IF(OR(A14="",D14=""),"",IF(D14<TIME(6,0,0),A14-1,A14)) -> 05/05 | J14: =IF(D14="","",IF(D14<TIME(6,0,0),"Nuit",IF(D14<TIME(14,0,0),"Matin",IF(D14<TIME(22,0,0),"Après-midi","Nuit")))) -> Après-midi
A15: 46147 | B15: B | C15: Bicoupe | D15: 0.81944444 | E15: 0.91666667 | F15: =IF(OR(D15="",E15=""),"",(MOD(E15-D15,1))*1440) -> 140 | G15: ok | H15: =IF(OR(D15="",E14="",C15<>C14,B15=B14),"",(MOD(D15-E14,1))*1440) | I15: =IF(OR(A15="",D15=""),"",IF(D15<TIME(6,0,0),A15-1,A15)) -> 05/05 | J15: =IF(D15="","",IF(D15<TIME(6,0,0),"Nuit",IF(D15<TIME(14,0,0),"Matin",IF(D15<TIME(22,0,0),"Après-midi","Nuit")))) -> Après-midi
A16: 46147 | B16: B | C16: Bicoupe | D16: 0.92708333 | E16: 0.99930556 | F16: =IF(OR(D16="",E16=""),"",(MOD(E16-D16,1))*1440) -> 104 | G16: ok | H16: =IF(OR(D16="",E15="",C16<>C15,B16=B15),"",(MOD(D16-E15,1))*1440) | I16: =IF(OR(A16="",D16=""),"",IF(D16<TIME(6,0,0),A16-1,A16)) -> 05/05 | J16: =IF(D16="","",IF(D16<TIME(6,0,0),"Nuit",IF(D16<TIME(14,0,0),"Matin",IF(D16<TIME(22,0,0),"Après-midi","Nuit")))) -> Nuit
A17: 46148 | B17: B | C17: Bicoupe | D17: 0.0090277778 | E17: 0.013888889 | F17: =IF(OR(D17="",E17=""),"",(MOD(E17-D17,1))*1440) -> 7 | G17: deviation | H17: =IF(OR(D17="",E16="",C17<>C16,B17=B16),"",(MOD(D17-E16,1))*1440) | I17: =IF(OR(A17="",D17=""),"",IF(D17<TIME(6,0,0),A17-1,A17)) -> 05/05 | J17: =IF(D17="","",IF(D17<TIME(6,0,0),"Nuit",IF(D17<TIME(14,0,0),"Matin",IF(D17<TIME(22,0,0),"Après-midi","Nuit")))) -> Nuit
A18: 46148 | B18: B | C18: Bicoupe | D18: 0.018055556 | E18: 0.16111111 | F18: =IF(OR(D18="",E18=""),"",(MOD(E18-D18,1))*1440) -> 206 | G18: ok | H18: =IF(OR(D18="",E17="",C18<>C17,B18=B17),"",(MOD(D18-E17,1))*1440) | I18: =IF(OR(A18="",D18=""),"",IF(D18<TIME(6,0,0),A18-1,A18)) -> 05/05 | J18: =IF(D18="","",IF(D18<TIME(6,0,0),"Nuit",IF(D18<TIME(14,0,0),"Matin",IF(D18<TIME(22,0,0),"Après-midi","Nuit")))) -> Nuit
A19: 46148 | B19: B | C19: Bicoupe | D19: 0.16875 | E19: 0.24027778 | F19: =IF(OR(D19="",E19=""),"",(MOD(E19-D19,1))*1440) -> 103 | G19: ok | H19: =IF(OR(D19="",E18="",C19<>C18,B19=B18),"",(MOD(D19-E18,1))*1440) | I19: =IF(OR(A19="",D19=""),"",IF(D19<TIME(6,0,0),A19-1,A19)) -> 05/05 | J19: =IF(D19="","",IF(D19<TIME(6,0,0),"Nuit",IF(D19<TIME(14,0,0),"Matin",IF(D19<TIME(22,0,0),"Après-midi","Nuit")))) -> Nuit
A20: 46148 | B20: A | C20: Bicoupe | D20: 0.25 | E20: 0.34027778 | F20: =IF(OR(D20="",E20=""),"",(MOD(E20-D20,1))*1440) -> 130 | G20: ok | H20: =IF(OR(D20="",E19="",C20<>C19,B20=B19),"",(MOD(D20-E19,1))*1440) -> 14 | I20: =IF(OR(A20="",D20=""),"",IF(D20<TIME(6,0,0),A20-1,A20)) -> 06/05 | J20: =IF(D20="","",IF(D20<TIME(6,0,0),"Nuit",IF(D20<TIME(14,0,0),"Matin",IF(D20<TIME(22,0,0),"Après-midi","Nuit")))) -> Matin
A21: 46148 | B21: A | C21: Bicoupe | D21: 0.35347222 | E21: 0.49861111 | F21: =IF(OR(D21="",E21=""),"",(MOD(E21-D21,1))*1440) -> 209 | G21: ok | H21: =IF(OR(D21="",E20="",C21<>C20,B21=B20),"",(MOD(D21-E20,1))*1440) | I21: =IF(OR(A21="",D21=""),"",IF(D21<TIME(6,0,0),A21-1,A21)) -> 06/05 | J21: =IF(D21="","",IF(D21<TIME(6,0,0),"Nuit",IF(D21<TIME(14,0,0),"Matin",IF(D21<TIME(22,0,0),"Après-midi","Nuit")))) -> Matin
A22: 46148 | B22: A | C22: Bicoupe | D22: 0.50555556 | E22: 0.58333333 | F22: =IF(OR(D22="",E22=""),"",(MOD(E22-D22,1))*1440) -> 112 | G22: ok | H22: =IF(OR(D22="",E21="",C22<>C21,B22=B21),"",(MOD(D22-E21,1))*1440) | I22: =IF(OR(A22="",D22=""),"",IF(D22<TIME(6,0,0),A22-1,A22)) -> 06/05 | J22: =IF(D22="","",IF(D22<TIME(6,0,0),"Nuit",IF(D22<TIME(14,0,0),"Matin",IF(D22<TIME(22,0,0),"Après-midi","Nuit")))) -> Matin
A23: 46148 | B23: B | C23: Bicoupe | D23: 0.58819444 | E23: 0.63541667 | F23: =IF(OR(D23="",E23=""),"",(MOD(E23-D23,1))*1440) -> 68 | G23: zéro | H23: =IF(OR(D23="",E22="",C23<>C22,B23=B22),"",(MOD(D23-E22,1))*1440) -> 7 | I23: =IF(OR(A23="",D23=""),"",IF(D23<TIME(6,0,0),A23-1,A23)) -> 06/05 | J23: =IF(D23="","",IF(D23<TIME(6,0,0),"Nuit",IF(D23<TIME(14,0,0),"Matin",IF(D23<TIME(22,0,0),"Après-midi","Nuit")))) -> Après-midi
... A56: 46151 | B56: A | C56: Bicoupe | D56: 0.47291667 | E56: 0.55416667 | F56: =IF(OR(D56="",E56=""),"",(MOD(E56-D56,1))*1440) -> 117 | G56: ok | H56: =IF(OR(D56="",E55="",C56<>C55,B56=B55),"",(MOD(D56-E55,1))*1440) | I56: =IF(OR(A56="",D56=""),"",IF(D56<TIME(6,0,0),A56-1,A56)) -> 09/05 | J56: =IF(D56="","",IF(D56<TIME(6,0,0),"Nuit",IF(D56<TIME(14,0,0),"Matin",IF(D56<TIME(22,0,0),"Après-midi","Nuit")))) -> Matin
A57: 46151 | B57: A | C57: Bicoupe | D57: 0.56041667 | E57: 0.58333333 | F57: =IF(OR(D57="",E57=""),"",(MOD(E57-D57,1))*1440) -> 33 | H57: =IF(OR(D57="",E56="",C57<>C56,B57=B56),"",(MOD(D57-E56,1))*1440) | I57: =IF(OR(A57="",D57=""),"",IF(D57<TIME(6,0,0),A57-1,A57)) -> 09/05 | J57: =IF(D57="","",IF(D57<TIME(6,0,0),"Nuit",IF(D57<TIME(14,0,0),"Matin",IF(D57<TIME(22,0,0),"Après-midi","Nuit")))) -> Matin
A58: 46151 | B58: B | C58: Bicoupe | D58: 0.58680556 | E58: 0.61805556 | F58: =IF(OR(D58="",E58=""),"",(MOD(E58-D58,1))*1440) -> 45 | G58: panne mécanique | H58: =IF(OR(D58="",E57="",C58<>C57,B58=B57),"",(MOD(D58-E57,1))*1440) -> 5 | I58: =IF(OR(A58="",D58=""),"",IF(D58<TIME(6,0,0),A58-1,A58)) -> 09/05 | J58: =IF(D58="","",IF(D58<TIME(6,0,0),"Nuit",IF(D58<TIME(14,0,0),"Matin",IF(D58<TIME(22,0,0),"Après-midi","Nuit")))) -> Après-midi
A59: 46151 | B59: B | C59: Bicoupe | D59: 0.63888889 | E59: 0.7 | F59: =IF(OR(D59="",E59=""),"",(MOD(E59-D59,1))*1440) -> 88 | G59: sciage un côté | H59: =IF(OR(D59="",E58="",C59<>C58,B59=B58),"",(MOD(D59-E58,1))*1440) | I59: =IF(OR(A59="",D59=""),"",IF(D59<TIME(6,0,0),A59-1,A59)) -> 09/05 | J59: =IF(D59="","",IF(D59<TIME(6,0,0),"Nuit",IF(D59<TIME(14,0,0),"Matin",IF(D59<TIME(22,0,0),"Après-midi","Nuit")))) -> Après-midi
A60: 46151 | B60: B | C60: Bicoupe | D60: 0.70694444 | E60: 0.84583333 | F60: =IF(OR(D60="",E60=""),"",(MOD(E60-D60,1))*1440) -> 200 | G60: ok | H60: =IF(OR(D60="",E59="",C60<>C59,B60=B59),"",(MOD(D60-E59,1))*1440) | I60: =IF(OR(A60="",D60=""),"",IF(D60<TIME(6,0,0),A60-1,A60)) -> 09/05 | J60: =IF(D60="","",IF(D60<TIME(6,0,0),"Nuit",IF(D60<TIME(14,0,0),"Matin",IF(D60<TIME(22,0,0),"Après-midi","Nuit")))) -> Après-midi
A61: 46151 | B61: B | C61: Bicoupe | D61: 0.85416667 | E61: 0.91666667 | F61: =IF(OR(D61="",E61=""),"",(MOD(E61-D61,1))*1440) -> 90 | G61: ok | H61: =IF(OR(D61="",E60="",C61<>C60,B61=B60),"",(MOD(D61-E60,1))*1440) | I61: =IF(OR(A61="",D61=""),"",IF(D61<TIME(6,0,0),A61-1,A61)) -> 09/05 | J61: =IF(D61="","",IF(D61<TIME(6,0,0),"Nuit",IF(D61<TIME(14,0,0),"Matin",IF(D61<TIME(22,0,0),"Après-midi","Nuit")))) -> Après-midi
A62: 46151 | B62: C | C62: Bicoupe | D62: 0.92013889 | E62: 0.022916667 | F62: =IF(OR(D62="",E62=""),"",(MOD(E62-D62,1))*1440) -> 148 | G62: ok | H62: =IF(OR(D62="",E61="",C62<>C61,B62=B61),"",(MOD(D62-E61,1))*1440) -> 5 | I62: =IF(OR(A62="",D62=""),"",IF(D62<TIME(6,0,0),A62-1,A62)) -> 09/05 | J62: =IF(D62="","",IF(D62<TIME(6,0,0),"Nuit",IF(D62<TIME(14,0,0),"Matin",IF(D62<TIME(22,0,0),"Après-midi","Nuit")))) -> Nuit
A63: 46152 | B63: C | C63: Bicoupe | D63: 0.035416667 | E63: 0.15902778 | F63: =IF(OR(D63="",E63=""),"",(MOD(E63-D63,1))*1440) -> 178 | G63: ok | H63: =IF(OR(D63="",E62="",C63<>C62,B63=B62),"",(MOD(D63-E62,1))*1440) | I63: =IF(OR(A63="",D63=""),"",IF(D63<TIME(6,0,0),A63-1,A63)) -> 09/05 | J63: =IF(D63="","",IF(D63<TIME(6,0,0),"Nuit",IF(D63<TIME(14,0,0),"Matin",IF(D63<TIME(22,0,0),"Après-midi","Nuit")))) -> Nuit
A64: 46152 | B64: C | C64: Bicoupe | D64: 0.16388889 | E64: 0.25 | F64: =IF(OR(D64="",E64=""),"",(MOD(E64-D64,1))*1440) -> 124 | G64: ok | H64: =IF(OR(D64="",E63="",C64<>C63,B64=B63),"",(MOD(D64-E63,1))*1440) | I64: =IF(OR(A64="",D64=""),"",IF(D64<TIME(6,0,0),A64-1,A64)) -> 09/05 | J64: =IF(D64="","",IF(D64<TIME(6,0,0),"Nuit",IF(D64<TIME(14,0,0),"Matin",IF(D64<TIME(22,0,0),"Après-midi","Nuit")))) -> Nuit
A65: 46152 | B65: A | C65: Bicoupe | D65: 0.25694444 | E65: 0.37152778 | F65: =IF(OR(D65="",E65=""),"",(MOD(E65-D65,1))*1440) -> 165 | G65: ok | H65: =IF(OR(D65="",E64="",C65<>C64,B65=B64),"",(MOD(D65-E64,1))*1440) -> 10 | I65: =IF(OR(A65="",D65=""),"",IF(D65<TIME(6,0,0),A65-1,A65)) -> 10/05 | J65: =IF(D65="","",IF(D65<TIME(6,0,0),"Nuit",IF(D65<TIME(14,0,0),"Matin",IF(D65<TIME(22,0,0),"Après-midi","Nuit")))) -> Matin
A66: 46152 | B66: A | C66: Bicoupe | D66: 0.37361111 | E66: 0.40625 | F66: =IF(OR(D66="",E66=""),"",(MOD(E66-D66,1))*1440) -> 47 | G66: deviation | H66: =IF(OR(D66="",E65="",C66<>C65,B66=B65),"",(MOD(D66-E65,1))*1440) | I66: =IF(OR(A66="",D66=""),"",IF(D66<TIME(6,0,0),A66-1,A66)) -> 10/05 | J66: =IF(D66="","",IF(D66<TIME(6,0,0),"Nuit",IF(D66<TIME(14,0,0),"Matin",IF(D66<TIME(22,0,0),"Après-midi","Nuit")))) -> Matin
A67: 46152 | B67: A | C67: Bicoupe | D67: 0.37569444 | E67: 0.48611111 | F67: =IF(OR(D67="",E67=""),"",(MOD(E67-D67,1))*1440) -> 159 | G67: deviation | H67: =IF(OR(D67="",E66="",C67<>C66,B67=B66),"",(MOD(D67-E66,1))*1440) | I67: =IF(OR(A67="",D67=""),"",IF(D67<TIME(6,0,0),A67-1,A67)) -> 10/05 | J67: =IF(D67="","",IF(D67<TIME(6,0,0),"Nuit",IF(D67<TIME(14,0,0),"Matin",IF(D67<TIME(22,0,0),"Après-midi","Nuit")))) -> Matin
A68: 46152 | B68: A | C68: Bicoupe | D68: 0.49861111 | E68: 0.58333333 | F68: =IF(OR(D68="",E68=""),"",(MOD(E68-D68,1))*1440) -> 122 | G68: ok | H68: =IF(OR(D68="",E67="",C68<>C67,B68=B67),"",(MOD(D68-E67,1))*1440) | I68: =IF(OR(A68="",D68=""),"",IF(D68<TIME(6,0,0),A68-1,A68)) -> 10/05 | J68: =IF(D68="","",IF(D68<TIME(6,0,0),"Nuit",IF(D68<TIME(14,0,0),"Matin",IF(D68<TIME(22,0,0),"Après-midi","Nuit")))) -> Matin
A69: 46153 | B69: B | C69: Bicoupe | D69: 0.26319444 | E69: 0.37569444 | F69: =IF(OR(D69="",E69=""),"",(MOD(E69-D69,1))*1440) -> 162 | G69: ok | H69: =IF(OR(D69="",E68="",C69<>C68,B69=B68),"",(MOD(D69-E68,1))*1440) -> 979 | I69: =IF(OR(A69="",D69=""),"",IF(D69<TIME(6,0,0),A69-1,A69)) -> 11/05 | J69: =IF(D69="","",IF(D69<TIME(6,0,0),"Nuit",IF(D69<TIME(14,0,0),"Matin",IF(D69<TIME(22,0,0),"Après-midi","Nuit")))) -> Matin
... A418: 46184 | B418: A | C418: Bicoupe | D418: 0.14375 | E418: 0.25 | F418: =IF(OR(D418="",E418=""),"",(MOD(E418-D418,1))*1440) -> 153 | G418: ok | H418: =IF(OR(D418="",E417="",C418<>C417,B418=B417),"",(MOD(D418-E417,1))*1440) | I418: =IF(OR(A418="",D418=""),"",IF(D418<TIME(6,0,0),A418-1,A418)) -> 10/06 | J418: =IF(D418="","",IF(D418<TIME(6,0,0),"Nuit",IF(D418<TIME(14,0,0),"Matin",IF(D418<TIME(22,0,0),"Après-midi","Nuit")))) -> Nuit
F419: =IF(OR(D419="",E419=""),"",(MOD(E419-D419,1))*1440) | H419: =IF(OR(D419="",E418="",C419<>C418,B419=B418),"",(MOD(D419-E418,1))*1440) | I419: =IF(OR(A419="",D419=""),"",IF(D419<TIME(6,0,0),A419-1,A419)) | J419: =IF(D419="","",IF(D419<TIME(6,0,0),"Nuit",IF(D419<TIME(14,0,0),"Matin",IF(D419<TIME(22,0,0),"Après-midi","Nuit"))))
A420: SESSIONS DE SCIAGE (heures début/fin) SHULTE | F420: =IF(OR(D420="",E420=""),"",(MOD(E420-D420,1))*1440) | H420: =IF(OR(D420="",E419="",C420<>C419,B420=B419),"",(MOD(D420-E419,1))*1440) | I420: =IF(OR(A420="",D420=""),"",IF(D420<TIME(6,0,0),A420-1,A420)) | J420: =IF(D420="","",IF(D420<TIME(6,0,0),"Nuit",IF(D420<TIME(14,0,0),"Matin",IF(D420<TIME(22,0,0),"Après-midi","Nuit"))))
...

Sheet 3-CHANGEMENTS LAMES
A1: CHANGEMENTS DE LAMES (feuille séparée)
A2: QUOI REMPLIR (jaune) : Date, Équipe, Machine, Heure début, Heure fin de chaque changement de lame.
A3: La durée se calcule seule. Chaque changement de lame est écrit ici, séparé des sessions. Plus de trou à deviner.
A4: Date | B4: Équipe | C4: Machine | D4: Heure début | E4: Heure fin | F4: Durée (min, auto) | G4: Note (facultatif) | H4: Date du quart (auto) | I4: Créneau (auto)
A5: 11/06 | B5: B | C5: Bicoupe | D5: 0.33333333 | E5: 0.34375 | F5: =IF(OR(D5="",E5=""),"",(E5-D5)*1440) -> 15 | H5: =IF(OR(A5="",D5=""),"",IF(D5<TIME(6,0,0),A5-1,A5)) -> 11/06 | I5: =IF(D5="","",IF(D5<TIME(6,0,0),"Nuit",IF(D5<TIME(14,0,0),"Matin",IF(D5<TIME(22,0,0),"Après-midi","Nuit")))) -> Matin
A6: 11/06 | B6: B | C6: Bicoupe | D6: 0.45833333 | E6: 0.46875 | F6: =IF(OR(D6="",E6=""),"",(E6-D6)*1440) -> 15 | H6: =IF(OR(A6="",D6=""),"",IF(D6<TIME(6,0,0),A6-1,A6)) -> 11/06 | I6: =IF(D6="","",IF(D6<TIME(6,0,0),"Nuit",IF(D6<TIME(14,0,0),"Matin",IF(D6<TIME(22,0,0),"Après-midi","Nuit")))) -> Matin
A7: 46147 | B7: B | C7: Bicoupe | D7: 0.67291667 | E7: 0.68958333 | F7: =IF(OR(D7="",E7=""),"",(E7-D7)*1440) -> 24 | H7: =IF(OR(A7="",D7=""),"",IF(D7<TIME(6,0,0),A7-1,A7)) -> 05/05 | I7: =IF(D7="","",IF(D7<TIME(6,0,0),"Nuit",IF(D7<TIME(14,0,0),"Matin",IF(D7<TIME(22,0,0),"Après-midi","Nuit")))) -> Après-midi
A8: 46147 | B8: B | C8: Bicoupe | D8: 0.8125 | E8: 0.81944444 | F8: =IF(OR(D8="",E8=""),"",(E8-D8)*1440) -> 10 | H8: =IF(OR(A8="",D8=""),"",IF(D8<TIME(6,0,0),A8-1,A8)) -> 05/05 | I8: =IF(D8="","",IF(D8<TIME(6,0,0),"Nuit",IF(D8<TIME(14,0,0),"Matin",IF(D8<TIME(22,0,0),"Après-midi","Nuit")))) -> Après-midi
A9: 46147 | B9: B | C9: Bicoupe | D9: 0.91666667 | E9: 0.92708333 | F9: =IF(OR(D9="",E9=""),"",(E9-D9)*1440) -> 15 | H9: =IF(OR(A9="",D9=""),"",IF(D9<TIME(6,0,0),A9-1,A9)) -> 05/05 | I9: =IF(D9="","",IF(D9<TIME(6,0,0),"Nuit",IF(D9<TIME(14,0,0),"Matin",IF(D9<TIME(22,0,0),"Après-midi","Nuit")))) -> Nuit
A10: 46148 | B10: B | C10: Bicoupe | D10: 0.013888889 | E10: 0.018055556 | F10: =IF(OR(D10="",E10=""),"",(E10-D10)*1440) -> 6 | H10: =IF(OR(A10="",D10=""),"",IF(D10<TIME(6,0,0),A10-1,A10)) -> 05/05 | I10: =IF(D10="","",IF(D10<TIME(6,0,0),"Nuit",IF(D10<TIME(14,0,0),"Matin",IF(D10<TIME(22,0,0),"Après-midi","Nuit")))) -> Nuit
A11: 46148 | B11: B | C11: Bicoupe | D11: 0.16111111 | E11: 0.16875 | F11: =IF(OR(D11="",E11=""),"",(E11-D11)*1440) -> 11 | H11: =IF(OR(A11="",D11=""),"",IF(D11<TIME(6,0,0),A11-1,A11)) -> 05/05 | I11: =IF(D11="","",IF(D11<TIME(6,0,0),"Nuit",IF(D11<TIME(14,0,0),"Matin",IF(D11<TIME(22,0,0),"Après-midi","Nuit")))) -> Nuit
A12: 46148 | B12: B | C12: Bicoupe | D12: 0.24027778 | E12: 0.25 | F12: =IF(OR(D12="",E12=""),"",(E12-D12)*1440) -> 14 | H12: =IF(OR(A12="",D12=""),"",IF(D12<TIME(6,0,0),A12-1,A12)) -> 05/05 | I12: =IF(D12="","",IF(D12<TIME(6,0,0),"Nuit",IF(D12<TIME(14,0,0),"Matin",IF(D12<TIME(22,0,0),"Après-midi","Nuit")))) -> Nuit
A13: 46148 | B13: A | C13: Bicoupe | D13: 0.34027778 | E13: 0.35347222 | F13: =IF(OR(D13="",E13=""),"",(E13-D13)*1440) -> 19 | H13: =IF(OR(A13="",D13=""),"",IF(D13<TIME(6,0,0),A13-1,A13)) -> 06/05 | I13: =IF(D13="","",IF(D13<TIME(6,0,0),"Nuit",IF(D13<TIME(14,0,0),"Matin",IF(D13<TIME(22,0,0),"Après-midi","Nuit")))) -> Matin
A14: 46148 | B14: A | C14: Bicoupe | D14: 0.49861111 | E14: 0.50555556 | F14: =IF(OR(D14="",E14=""),"",(E14-D14)*1440) -> 10 | H14: =IF(OR(A14="",D14=""),"",IF(D14<TIME(6,0,0),A14-1,A14)) -> 06/05 | I14: =IF(D14="","",IF(D14<TIME(6,0,0),"Nuit",IF(D14<TIME(14,0,0),"Matin",IF(D14<TIME(22,0,0),"Après-midi","Nuit")))) -> Matin
A15: 46148 | B15: A | C15: Bicoupe | D15: 0.58333333 | E15: 0.58819444 | F15: =IF(OR(D15="",E15=""),"",(E15-D15)*1440) -> 7 | H15: =IF(OR(A15="",D15=""),"",IF(D15<TIME(6,0,0),A15-1,A15)) -> 06/05 | I15: =IF(D15="","",IF(D15<TIME(6,0,0),"Nuit",IF(D15<TIME(14,0,0),"Matin",IF(D15<TIME(22,0,0),"Après-midi","Nuit")))) -> Après-midi
A16: 46148 | B16: B | C16: Bicoupe | D16: 0.63541667 | E16: 0.64236111 | F16: =IF(OR(D16="",E16=""),"",(E16-D16)*1440) -> 10 | H16: =IF(OR(A16="",D16=""),"",IF(D16<TIME(6,0,0),A16-1,A16)) -> 06/05 | I16: =IF(D16="","",IF(D16<TIME(6,0,0),"Nuit",IF(D16<TIME(14,0,0),"Matin",IF(D16<TIME(22,0,0),"Après-midi","Nuit")))) -> Après-midi
A17: 46148 | B17: B | C17: Bicoupe | D17: 0.77083333 | E17: 0.77430556 | F17: =IF(OR(D17="",E17=""),"",(E17-D17)*1440) -> 5 | H17: =IF(OR(A17="",D17=""),"",IF(D17<TIME(6,0,0),A17-1,A17)) -> 06/05 | I17: =IF(D17="","",IF(D17<TIME(6,0,0),"Nuit",IF(D17<TIME(14,0,0),"Matin",IF(D17<TIME(22,0,0),"Après-midi","Nuit")))) -> Après-midi
A18: 46148 | B18: B | C18: Bicoupe | D18: 0.91666667 | E18: 0.92847222 | F18: =IF(OR(D18="",E18=""),"",(E18-D18)*1440) -> 17 | H18: =IF(OR(A18="",D18=""),"",IF(D18<TIME(6,0,0),A18-1,A18)) -> 06/05 | I18: =IF(D18="","",IF(D18<TIME(6,0,0),"Nuit",IF(D18<TIME(14,0,0),"Matin",IF(D18<TIME(22,0,0),"Après-midi","Nuit")))) -> Nuit
... A495: 46185 | B495: A | C495: Schulte (scie de tête) | D495: 0.51388889 | E495: 0.52777778 | F495: =IF(OR(D495="",E495=""),"",(E495-D495)*1440) -> 20 | H495: =IF(OR(A495="",D495=""),"",IF(D495<TIME(6,0,0),A495-1,A495)) -> 12/06 | I495: =IF(D495="","",IF(D495<TIME(6,0,0),"Nuit",IF(D495<TIME(14,0,0),"Matin",IF(D495<TIME(22,0,0),"Après-midi","Nuit")))) -> Matin

Sheet 4-BILAN PAR POSTE
A1: BILAN PAR POSTE (automatique)
A2: QUOI REMPLIR (jaune) : Date, Équipe, Machine. Tout le reste s'additionne depuis les feuilles 2 et 3.
A4: Date quart | B4: Créneau | C4: Machine | D4: Sciage bon (min) | E4: Sciage dégradé (min) | F4: Arrêt panne/zéro (min) | G4: Chgt lame (min) | H4: Retard relève (min) | I4: Arrêt total (min) | J4: TOTAL activité (min)
A5: 46147 | B5: Après-midi | C5: Bicoupe | D5: =SUMIFS('2-SESSIONS SCIAGE'!$F:$F,'2-SESSIONS SCIAGE'!$I:$I,$A5,'2-SESSIONS SCIAGE'!$J:$J,$B5,'2-SESSIONS SCIAGE'!$C:$C,$C5,'2-SESSIONS SCIAGE'!$G:$G,"ok") -> 413 | E5: =SUMIFS('2-SESSIONS SCIAGE'!$F:$F,'2-SESSIONS SCIAGE'!$I:$I,$A5,'2-SESSIONS SCIAGE'!$J:$J,$B5,'2-SESSIONS SCIAGE'!$C:$C,$C5,'2-SESSIONS SCIAGE'!$G:$G,"sciage un côté")+SUMIFS('2-SESSIONS SCIAGE'!$F:$F,'2-SESSIONS SCIAGE'!$I:$I,$A5,'2-SESSIONS SCIAGE'!$J:$J,$B5,'2-SESSIONS SCIAGE'!$C:$C,$C5,'2-SESSIONS SCIAGE'!$G:$G,"mauvaise épaisseur")+SUMIFS('2-SESSIONS SCIAGE'!$F:$F,'2-SESSIONS SCIAGE'!$I:$I,$A5,'2-SESSIONS SCIAGE'!$J:$J,$B5,'2-SESSIONS SCIAGE'!$C:$C,$C5,'2-SESSIONS SCIAGE'!$G:$G,"rayures")+SUMIFS('2-SESSIONS SCIAGE'!$F:$F,'2-SESSIONS SCIAGE'!$I:$I,$A5,'2-SESSIONS SCIAGE'!$J:$J,$B5,'2-SESSIONS SCIAGE'!$C:$C,$C5,'2-SESSIONS SCIAGE'!$G:$G,"deviation") -> 0 | F5: =SUMIFS('2-SESSIONS SCIAGE'!$F:$F,'2-SESSIONS SCIAGE'!$I:$I,$A5,'2-SESSIONS SCIAGE'!$J:$J,$B5,'2-SESSIONS SCIAGE'!$C:$C,$C5,'2-SESSIONS SCIAGE'!$G:$G,"zéro")+SUMIFS('2-SESSIONS SCIAGE'!$F:$F,'2-SESSIONS SCIAGE'!$I:$I,$A5,'2-SESSIONS SCIAGE'!$J:$J,$B5,'2-SESSIONS SCIAGE'!$C:$C,$C5,'2-SESSIONS SCIAGE'!$G:$G,"panne mécanique")+SUMIFS('2-SESSIONS SCIAGE'!$F:$F,'2-SESSIONS SCIAGE'!$I:$I,$A5,'2-SESSIONS SCIAGE'!$J:$J,$B5,'2-SESSIONS SCIAGE'!$C:$C,$C5,'2-SESSIONS SCIAGE'!$G:$G,"panne électrique") -> 33 | G5: =SUMIFS('3-CHANGEMENTS LAMES'!$F:$F,'3-CHANGEMENTS LAMES'!$H:$H,$A5,'3-CHANGEMENTS LAMES'!$I:$I,$B5,'3-CHANGEMENTS LAMES'!$C:$C,$C5) -> 34 | H5: =SUMIFS('2-SESSIONS SCIAGE'!$H:$H,'2-SESSIONS SCIAGE'!$I:$I,$A5,'2-SESSIONS SCIAGE'!$J:$J,$B5,'2-SESSIONS SCIAGE'!$C:$C,$C5) -> 0 | I5: =F5+G5+H5 -> 67 | J5: =D5+E5+I5 -> 480
A6: 46147 | B6: Nuit | C6: Bicoupe | D6: =SUMIFS('2-SESSIONS SCIAGE'!$F:$F,'2-SESSIONS SCIAGE'!$I:$I,$A6,'2-SESSIONS SCIAGE'!$J:$J,$B6,'2-SESSIONS SCIAGE'!$C:$C,$C6,'2-SESSIONS SCIAGE'!$G:$G,"ok") -> 413 | E6: =SUMIFS('2-SESSIONS SCIAGE'!$F:$F,'2-SESSIONS SCIAGE'!$I:$I,$A6,'2-SESSIONS SCIAGE'!$J:$J,$B6,'2-SESSIONS SCIAGE'!$C:$C,$C6,'2-SESSIONS SCIAGE'!$G:$G,"sciage un côté")+SUMIFS('2-SESSIONS SCIAGE'!$F:$F,'2-SESSIONS SCIAGE'!$I:$I,$A6,'2-SESSIONS SCIAGE'!$J:$J,$B6,'2-SESSIONS SCIAGE'!$C:$C,$C6,'2-SESSIONS SCIAGE'!$G:$G,"mauvaise épaisseur")+SUMIFS('2-SESSIONS SCIAGE'!$F:$F,'2-SESSIONS SCIAGE'!$I:$I,$A6,'2-SESSIONS SCIAGE'!$J:$J,$B6,'2-SESSIONS SCIAGE'!$C:$C,$C6,'2-SESSIONS SCIAGE'!$G:$G,"rayures")+SUMIFS('2-SESSIONS SCIAGE'!$F:$F,'2-SESSIONS SCIAGE'!$I:$I,$A6,'2-SESSIONS SCIAGE'!$J:$J,$B6,'2-SESSIONS SCIAGE'!$C:$C,$C6,'2-SESSIONS SCIAGE'!$G:$G,"deviation") -> 7 | F6: =SUMIFS('2-SESSIONS SCIAGE'!$F:$F,'2-SESSIONS SCIAGE'!$I:$I,$A6,'2-SESSIONS SCIAGE'!$J:$J,$B6,'2-SESSIONS SCIAGE'!$C:$C,$C6,'2-SESSIONS SCIAGE'!$G:$G,"zéro")+SUMIFS('2-SESSIONS SCIAGE'!$F:$F,'2-SESSIONS SCIAGE'!$I:$I,$A6,'2-SESSIONS SCIAGE'!$J:$J,$B6,'2-SESSIONS SCIAGE'!$C:$C,$C6,'2-SESSIONS SCIAGE'!$G:$G,"panne mécanique")+SUMIFS('2-SESSIONS SCIAGE'!$F:$F,'2-SESSIONS SCIAGE'!$I:$I,$A6,'2-SESSIONS SCIAGE'!$J:$J,$B6,'2-SESSIONS SCIAGE'!$C:$C,$C6,'2-SESSIONS SCIAGE'!$G:$G,"panne électrique") -> 0 | G6: =SUMIFS('3-CHANGEMENTS LAMES'!$F:$F,'3-CHANGEMENTS LAMES'!$H:$H,$A6,'3-CHANGEMENTS LAMES'!$I:$I,$B6,'3-CHANGEMENTS LAMES'!$C:$C,$C6) -> 46 | H6: =SUMIFS('2-SESSIONS SCIAGE'!$H:$H,'2-SESSIONS SCIAGE'!$I:$I,$A6,'2-SESSIONS SCIAGE'!$J:$J,$B6,'2-SESSIONS SCIAGE'!$C:$C,$C6) -> 0 | I6: =F6+G6+H6 -> 46 | J6: =D6+E6+I6 -> 466
A7: 46148 | B7: Matin | C7: Bicoupe | D7: =SUMIFS('2-SESSIONS SCIAGE'!$F:$F,'2-SESSIONS SCIAGE'!$I:$I,$A7,'2-SESSIONS SCIAGE'!$J:$J,$B7,'2-SESSIONS SCIAGE'!$C:$C,$C7,'2-SESSIONS SCIAGE'!$G:$G,"ok") -> 451 | E7: =SUMIFS('2-SESSIONS SCIAGE'!$F:$F,'2-SESSIONS SCIAGE'!$I:$I,$A7,'2-SESSIONS SCIAGE'!$J:$J,$B7,'2-SESSIONS SCIAGE'!$C:$C,$C7,'2-SESSIONS SCIAGE'!$G:$G,"sciage un côté")+SUMIFS('2-SESSIONS SCIAGE'!$F:$F,'2-SESSIONS SCIAGE'!$I:$I,$A7,'2-SESSIONS SCIAGE'!$J:$J,$B7,'2-SESSIONS SCIAGE'!$C:$C,$C7,'2-SESSIONS SCIAGE'!$G:$G,"mauvaise épaisseur")+SUMIFS('2-SESSIONS SCIAGE'!$F:$F,'2-SESSIONS SCIAGE'!$I:$I,$A7,'2-SESSIONS SCIAGE'!$J:$J,$B7,'2-SESSIONS SCIAGE'!$C:$C,$C7,'2-SESSIONS SCIAGE'!$G:$G,"rayures")+SUMIFS('2-SESSIONS SCIAGE'!$F:$F,'2-SESSIONS SCIAGE'!$I:$I,$A7,'2-SESSIONS SCIAGE'!$J:$J,$B7,'2-SESSIONS SCIAGE'!$C:$C,$C7,'2-SESSIONS SCIAGE'!$G:$G,"deviation") -> 0 | F7: =SUMIFS('2-SESSIONS SCIAGE'!$F:$F,'2-SESSIONS SCIAGE'!$I:$I,$A7,'2-SESSIONS SCIAGE'!$J:$J,$B7,'2-SESSIONS SCIAGE'!$C:$C,$C7,'2-SESSIONS SCIAGE'!$G:$G,"zéro")+SUMIFS('2-SESSIONS SCIAGE'!$F:$F,'2-SESSIONS SCIAGE'!$I:$I,$A7,'2-SESSIONS SCIAGE'!$J:$J,$B7,'2-SESSIONS SCIAGE'!$C:$C,$C7,'2-SESSIONS SCIAGE'!$G:$G,"panne mécanique")+SUMIFS('2-SESSIONS SCIAGE'!$F:$F,'2-SESSIONS SCIAGE'!$I:$I,$A7,'2-SESSIONS SCIAGE'!$J:$J,$B7,'2-SESSIONS SCIAGE'!$C:$C,$C7,'2-SESSIONS SCIAGE'!$G:$G,"panne électrique") -> 0 | G7: =SUMIFS('3-CHANGEMENTS LAMES'!$F:$F,'3-CHANGEMENTS LAMES'!$H:$H,$A7,'3-CHANGEMENTS LAMES'!$I:$I,$B7,'3-CHANGEMENTS LAMES'!$C:$C,$C7) -> 29 | H7: =SUMIFS('2-SESSIONS SCIAGE'!$H:$H,'2-SESSIONS SCIAGE'!$I:$I,$A7,'2-SESSIONS SCIAGE'!$J:$J,$B7,'2-SESSIONS SCIAGE'!$C:$C,$C7) -> 14 | I7: =F7+G7+H7 -> 43 | J7: =D7+E7+I7 -> 494
A8: 46148 | B8: Après-midi | C8: Bicoupe | D8: =SUMIFS('2-SESSIONS SCIAGE'!$F:$F,'2-SESSIONS SCIAGE'!$I:$I,$A8,'2-SESSIONS SCIAGE'!$J:$J,$B8,'2-SESSIONS SCIAGE'!$C:$C,$C8,'2-SESSIONS SCIAGE'!$G:$G,"ok") -> 390 | E8: =SUMIFS('2-SESSIONS SCIAGE'!$F:$F,'2-SESSIONS SCIAGE'!$I:$I,$A8,'2-SESSIONS SCIAGE'!$J:$J,$B8,'2-SESSIONS SCIAGE'!$C:$C,$C8,'2-SESSIONS SCIAGE'!$G:$G,"sciage un côté")+SUMIFS('2-SESSIONS SCIAGE'!$F:$F,'2-SESSIONS SCIAGE'!$I:$I,$A8,'2-SESSIONS SCIAGE'!$J:$J,$B8,'2-SESSIONS SCIAGE'!$C:$C,$C8,'2-SESSIONS SCIAGE'!$G:$G,"mauvaise épaisseur")+SUMIFS('2-SESSIONS SCIAGE'!$F:$F,'2-SESSIONS SCIAGE'!$I:$I,$A8,'2-SESSIONS SCIAGE'!$J:$J,$B8,'2-SESSIONS SCIAGE'!$C:$C,$C8,'2-SESSIONS SCIAGE'!$G:$G,"rayures")+SUMIFS('2-SESSIONS SCIAGE'!$F:$F,'2-SESSIONS SCIAGE'!$I:$I,$A8,'2-SESSIONS SCIAGE'!$J:$J,$B8,'2-SESSIONS SCIAGE'!$C:$C,$C8,'2-SESSIONS SCIAGE'!$G:$G,"deviation") -> 0 | F8: =SUMIFS('2-SESSIONS SCIAGE'!$F:$F,'2-SESSIONS SCIAGE'!$I:$I,$A8,'2-SESSIONS SCIAGE'!$J:$J,$B8,'2-SESSIONS SCIAGE'!$C:$C,$C8,'2-SESSIONS SCIAGE'!$G:$G,"zéro")+SUMIFS('2-SESSIONS SCIAGE'!$F:$F,'2-SESSIONS SCIAGE'!$I:$I,$A8,'2-SESSIONS SCIAGE'!$J:$J,$B8,'2-SESSIONS SCIAGE'!$C:$C,$C8,'2-SESSIONS SCIAGE'!$G:$G,"panne mécanique")+SUMIFS('2-SESSIONS SCIAGE'!$F:$F,'2-SESSIONS SCIAGE'!$I:$I,$A8,'2-SESSIONS SCIAGE'!$J:$J,$B8,'2-SESSIONS SCIAGE'!$C:$C,$C8,'2-SESSIONS SCIAGE'!$G:$G,"panne électrique") -> 68 | G8: =SUMIFS('3-CHANGEMENTS LAMES'!$F:$F,'3-CHANGEMENTS LAMES'!$H:$H,$A8,'3-CHANGEMENTS LAMES'!$I:$I,$B8,'3-CHANGEMENTS LAMES'!$C:$C,$C8) -> 22 | H8: =SUMIFS('2-SESSIONS SCIAGE'!$H:$H,'2-SESSIONS SCIAGE'!$I:$I,$A8,'2-SESSIONS SCIAGE'!$J:$J,$B8,'2-SESSIONS SCIAGE'!$C:$C,$C8) -> 7 | I8: =F8+G8+H8 -> 97 | J8: =D8+E8+I8 -> 487
A9: 46148 | B9: Nuit | C9: Bicoupe | D9: =SUMIFS('2-SESSIONS SCIAGE'!$F:$F,'2-SESSIONS SCIAGE'!$I:$I,$A9,'2-SESSIONS SCIAGE'!$J:$J,$B9,'2-SESSIONS SCIAGE'!$C:$C,$C9,'2-SESSIONS SCIAGE'!$G:$G,"ok") -> 424 | E9: =SUMIFS('2-SESSIONS SCIAGE'!$F:$F,'2-SESSIONS SCIAGE'!$I:$I,$A9,'2-SESSIONS SCIAGE'!$J:$J,$B9,'2-SESSIONS SCIAGE'!$C:$C,$C9,'2-SESSIONS SCIAGE'!$G:$G,"sciage un côté")+SUMIFS('2-SESSIONS SCIAGE'!$F:$F,'2-SESSIONS SCIAGE'!$I:$I,$A9,'2-SESSIONS SCIAGE'!$J:$J,$B9,'2-SESSIONS SCIAGE'!$C:$C,$C9,'2-SESSIONS SCIAGE'!$G:$G,"mauvaise épaisseur")+SUMIFS('2-SESSIONS SCIAGE'!$F:$F,'2-SESSIONS SCIAGE'!$I:$I,$A9,'2-SESSIONS SCIAGE'!$J:$J,$B9,'2-SESSIONS SCIAGE'!$C:$C,$C9,'2-SESSIONS SCIAGE'!$G:$G,"rayures")+SUMIFS('2-SESSIONS SCIAGE'!$F:$F,'2-SESSIONS SCIAGE'!$I:$I,$A9,'2-SESSIONS SCIAGE'!$J:$J,$B9,'2-SESSIONS SCIAGE'!$C:$C,$C9,'2-SESSIONS SCIAGE'!$G:$G,"deviation") -> 0 | F9: =SUMIFS('2-SESSIONS SCIAGE'!$F:$F,'2-SESSIONS SCIAGE'!$I:$I,$A9,'2-SESSIONS SCIAGE'!$J:$J,$B9,'2-SESSIONS SCIAGE'!$C:$C,$C9,'2-SESSIONS SCIAGE'!$G:$G,"zéro")+SUMIFS('2-SESSIONS SCIAGE'!$F:$F,'2-SESSIONS SCIAGE'!$I:$I,$A9,'2-SESSIONS SCIAGE'!$J:$J,$B9,'2-SESSIONS SCIAGE'!$C:$C,$C9,'2-SESSIONS SCIAGE'!$G:$G,"panne mécanique")+SUMIFS('2-SESSIONS SCIAGE'!$F:$F,'2-SESSIONS SCIAGE'!$I:$I,$A9,'2-SESSIONS SCIAGE'!$J:$J,$B9,'2-SESSIONS SCIAGE'!$C:$C,$C9,'2-SESSIONS SCIAGE'!$G:$G,"panne électrique") -> 0 | G9: =SUMIFS('3-CHANGEMENTS LAMES'!$F:$F,'3-CHANGEMENTS LAMES'!$H:$H,$A9,'3-CHANGEMENTS LAMES'!$I:$I,$B9,'3-CHANGEMENTS LAMES'!$C:$C,$C9) -> 29 | H9: =SUMIFS('2-SESSIONS SCIAGE'!$H:$H,'2-SESSIONS SCIAGE'!$I:$I,$A9,'2-SESSIONS SCIAGE'!$J:$J,$B9,'2-SESSIONS SCIAGE'!$C:$C,$C9) -> 17 | I9: =F9+G9+H9 -> 46 | J9: =D9+E9+I9 -> 470
A10: 46149 | B10: Matin | C10: Bicoupe | D10: =SUMIFS('2-SESSIONS SCIAGE'!$F:$F,'2-SESSIONS SCIAGE'!$I:$I,$A10,'2-SESSIONS SCIAGE'!$J:$J,$B10,'2-SESSIONS SCIAGE'!$C:$C,$C10,'2-SESSIONS SCIAGE'!$G:$G,"ok") -> 214 | E10: =SUMIFS('2-SESSIONS SCIAGE'!$F:$F,'2-SESSIONS SCIAGE'!$I:$I,$A10,'2-SESSIONS SCIAGE'!$J:$J,$B10,'2-SESSIONS SCIAGE'!$C:$C,$C10,'2-SESSIONS SCIAGE'!$G:$G,"sciage un côté")+SUMIFS('2-SESSIONS SCIAGE'!$F:$F,'2-SESSIONS SCIAGE'!$I:$I,$A10,'2-SESSIONS SCIAGE'!$J:$J,$B10,'2-SESSIONS SCIAGE'!$C:$C,$C10,'2-SESSIONS SCIAGE'!$G:$G,"mauvaise épaisseur")+SUMIFS('2-SESSIONS SCIAGE'!$F:$F,'2-SESSIONS SCIAGE'!$I:$I,$A10,'2-SESSIONS SCIAGE'!$J:$J,$B10,'2-SESSIONS SCIAGE'!$C:$C,$C10,'2-SESSIONS SCIAGE'!$G:$G,"rayures")+SUMIFS('2-SESSIONS SCIAGE'!$F:$F,'2-SESSIONS SCIAGE'!$I:$I,$A10,'2-SESSIONS SCIAGE'!$J:$J,$B10,'2-SESSIONS SCIAGE'!$C:$C,$C10,'2-SESSIONS SCIAGE'!$G:$G,"deviation") -> 224 | F10: =SUMIFS('2-SESSIONS SCIAGE'!$F:$F,'2-SESSIONS SCIAGE'!$I:$I,$A10,'2-SESSIONS SCIAGE'!$J:$J,$B10,'2-SESSIONS SCIAGE'!$C:$C,$C10,'2-SESSIONS SCIAGE'!$G:$G,"zéro")+SUMIFS('2-SESSIONS SCIAGE'!$F:$F,'2-SESSIONS SCIAGE'!$I:$I,$A10,'2-SESSIONS SCIAGE'!$J:$J,$B10,'2-SESSIONS SCIAGE'!$C:$C,$C10,'2-SESSIONS SCIAGE'!$G:$G,"panne mécanique")+SUMIFS('2-SESSIONS SCIAGE'!$F:$F,'2-SESSIONS SCIAGE'!$I:$I,$A10,'2-SESSIONS SCIAGE'!$J:$J,$B10,'2-SESSIONS SCIAGE'!$C:$C,$C10,'2-SESSIONS SCIAGE'!$G:$G,"panne électrique") -> 0 | G10: =SUMIFS('3-CHANGEMENTS LAMES'!$F:$F,'3-CHANGEMENTS LAMES'!$H:$H,$A10,'3-CHANGEMENTS LAMES'!$I:$I,$B10,'3-CHANGEMENTS LAMES'!$C:$C,$C10) -> 42 | H10: =SUMIFS('2-SESSIONS SCIAGE'!$H:$H,'2-SESSIONS SCIAGE'!$I:$I,$A10,'2-SESSIONS SCIAGE'!$J:$J,$B10,'2-SESSIONS SCIAGE'!$C:$C,$C10) -> 5 | I10: =F10+G10+H10 -> 47 | J10: =D10+E10+I10 -> 485
A11: 46149 | B11: Après-midi | C11: Bicoupe | D11: =SUMIFS('2-SESSIONS SCIAGE'!$F:$F,'2-SESSIONS SCIAGE'!$I:$I,$A11,'2-SESSIONS SCIAGE'!$J:$J,$B11,'2-SESSIONS SCIAGE'!$C:$C,$C11,'2-SESSIONS SCIAGE'!$G:$G,"ok") -> 404 | E11: =SUMIFS('2-SESSIONS SCIAGE'!$F:$F,'2-SESSIONS SCIAGE'!$I:$I,$A11,'2-SESSIONS SCIAGE'!$J:$J,$B11,'2-SESSIONS SCIAGE'!$C:$C,$C11,'2-SESSIONS SCIAGE'!$G:$G,"sciage un côté")+SUMIFS('2-SESSIONS SCIAGE'!$F:$F,'2-SESSIONS SCIAGE'!$I:$I,$A11,'2-SESSIONS SCIAGE'!$J:$J,$B11,'2-SESSIONS SCIAGE'!$C:$C,$C11,'2-SESSIONS SCIAGE'!$G:$G,"mauvaise épaisseur")+SUMIFS('2-SESSIONS SCIAGE'!$F:$F,'2-SESSIONS SCIAGE'!$I:$I,$A11,'2-SESSIONS SCIAGE'!$J:$J,$B11,'2-SESSIONS SCIAGE'!$C:$C,$C11,'2-SESSIONS SCIAGE'!$G:$G,"rayures")+SUMIFS('2-SESSIONS SCIAGE'!$F:$F,'2-SESSIONS SCIAGE'!$I:$I,$A11,'2-SESSIONS SCIAGE'!$J:$J,$B11,'2-SESSIONS SCIAGE'!$C:$C,$C11,'2-SESSIONS SCIAGE'!$G:$G,"deviation") -> 0 | F11: =SUMIFS('2-SESSIONS SCIAGE'!$F:$F,'2-SESSIONS SCIAGE'!$I:$I,$A11,'2-SESSIONS SCIAGE'!$J:$J,$B11,'2-SESSIONS SCIAGE'!$C:$C,$C11,'2-SESSIONS SCIAGE'!$G:$G,"zéro")+SUMIFS('2-SESSIONS SCIAGE'!$F:$F,'2-SESSIONS SCIAGE'!$I:$I,$A11,'2-SESSIONS SCIAGE'!$J:$J,$B11,'2-SESSIONS SCIAGE'!$C:$C,$C11,'2-SESSIONS SCIAGE'!$G:$G,"panne mécanique")+SUMIFS('2-SESSIONS SCIAGE'!$F:$F,'2-SESSIONS SCIAGE'!$I:$I,$A11,'2-SESSIONS SCIAGE'!$J:$J,$B11,'2-SESSIONS SCIAGE'!$C:$C,$C11,'2-SESSIONS SCIAGE'!$G:$G,"panne électrique") -> 26 | G11: =SUMIFS('3-CHANGEMENTS LAMES'!$F:$F,'3-CHANGEMENTS LAMES'!$H:$H,$A11,'3-CHANGEMENTS LAMES'!$I:$I,$B11,'3-CHANGEMENTS LAMES'!$C:$C,$C11) -> 50 | H11: =SUMIFS('2-SESSIONS SCIAGE'!$H:$H,'2-SESSIONS SCIAGE'!$I:$I,$A11,'2-SESSIONS SCIAGE'!$J:$J,$B11,'2-SESSIONS SCIAGE'!$C:$C,$C11) -> 15 | I11: =F11+G11+H11 -> 91 | J11: =D11+E11+I11 -> 495
A12: 46149 | B12: Nuit | C12: Bicoupe | D12: =SUMIFS('2-SESSIONS SCIAGE'!$F:$F,'2-SESSIONS SCIAGE'!$I:$I,$A12,'2-SESSIONS SCIAGE'!$J:$J,$B12,'2-SESSIONS SCIAGE'!$C:$C,$C12,'2-SESSIONS SCIAGE'!$G:$G,"ok") -> 452 | E12: =SUMIFS('2-SESSIONS SCIAGE'!$F:$F,'2-SESSIONS SCIAGE'!$I:$I,$A12,'2-SESSIONS SCIAGE'!$J:$J,$B12,'2-SESSIONS SCIAGE'!$C:$C,$C12,'2-SESSIONS SCIAGE'!$G:$G,"sciage un côté")+SUMIFS('2-SESSIONS SCIAGE'!$F:$F,'2-SESSIONS SCIAGE'!$I:$I,$A12,'2-SESSIONS SCIAGE'!$J:$J,$B12,'2-SESSIONS SCIAGE'!$C:$C,$C12,'2-SESSIONS SCIAGE'!$G:$G,"mauvaise épaisseur")+SUMIFS('2-SESSIONS SCIAGE'!$F:$F,'2-SESSIONS SCIAGE'!$I:$I,$A12,'2-SESSIONS SCIAGE'!$J:$J,$B12,'2-SESSIONS SCIAGE'!$C:$C,$C12,'2-SESSIONS SCIAGE'!$G:$G,"rayures")+SUMIFS('2-SESSIONS SCIAGE'!$F:$F,'2-SESSIONS SCIAGE'!$I:$I,$A12,'2-SESSIONS SCIAGE'!$J:$J,$B12,'2-SESSIONS SCIAGE'!$C:$C,$C12,'2-SESSIONS SCIAGE'!$G:$G,"deviation") -> 0 | F12: =SUMIFS('2-SESSIONS SCIAGE'!$F:$F,'2-SESSIONS SCIAGE'!$I:$I,$A12,'2-SESSIONS SCIAGE'!$J:$J,$B12,'2-SESSIONS SCIAGE'!$C:$C,$C12,'2-SESSIONS SCIAGE'!$G:$G,"zéro")+SUMIFS('2-SESSIONS SCIAGE'!$F:$F,'2-SESSIONS SCIAGE'!$I:$I,$A12,'2-SESSIONS SCIAGE'!$J:$J,$B12,'2-SESSIONS SCIAGE'!$C:$C,$C12,'2-SESSIONS SCIAGE'!$G:$G,"panne mécanique")+SUMIFS('2-SESSIONS SCIAGE'!$F:$F,'2-SESSIONS SCIAGE'!$I:$I,$A12,'2-SESSIONS SCIAGE'!$J:$J,$B12,'2-SESSIONS SCIAGE'!$C:$C,$C12,'2-SESSIONS SCIAGE'!$G:$G,"panne électrique") -> 0 | G12: =SUMIFS('3-CHANGEMENTS LAMES'!$F:$F,'3-CHANGEMENTS LAMES'!$H:$H,$A12,'3-CHANGEMENTS LAMES'!$I:$I,$B12,'3-CHANGEMENTS LAMES'!$C:$C,$C12) -> 13 | H12: =SUMIFS('2-SESSIONS SCIAGE'!$H:$H,'2-SESSIONS SCIAGE'!$I:$I,$A12,'2-SESSIONS SCIAGE'!$J:$J,$B12,'2-SESSIONS SCIAGE'!$C:$C,$C12) -> 3 | I12: =F12+G12+H12 -> 16 | J12: =D12+E12+I12 -> 468
A13: 46150 | B13: Matin | C13: Bicoupe | D13: =SUMIFS('2-SESSIONS SCIAGE'!$F:$F,'2-SESSIONS SCIAGE'!$I:$I,$A13,'2-SESSIONS SCIAGE'!$J:$J,$B13,'2-SESSIONS SCIAGE'!$C:$C,$C13,'2-SESSIONS SCIAGE'!$G:$G,"ok") -> 271 | E13: =SUMIFS('2-SESSIONS SCIAGE'!$F:$F,'2-SESSIONS SCIAGE'!$I:$I,$A13,'2-SESSIONS SCIAGE'!$J:$J,$B13,'2-SESSIONS SCIAGE'!$C:$C,$C13,'2-SESSIONS SCIAGE'!$G:$G,"sciage un côté")+SUMIFS('2-SESSIONS SCIAGE'!$F:$F,'2-SESSIONS SCIAGE'!$I:$I,$A13,'2-SESSIONS SCIAGE'!$J:$J,$B13,'2-SESSIONS SCIAGE'!$C:$C,$C13,'2-SESSIONS SCIAGE'!$G:$G,"mauvaise épaisseur")+SUMIFS('2-SESSIONS SCIAGE'!$F:$F,'2-SESSIONS SCIAGE'!$I:$I,$A13,'2-SESSIONS SCIAGE'!$J:$J,$B13,'2-SESSIONS SCIAGE'!$C:$C,$C13,'2-SESSIONS SCIAGE'!$G:$G,"rayures")+SUMIFS('2-SESSIONS SCIAGE'!$F:$F,'2-SESSIONS SCIAGE'!$I:$I,$A13,'2-SESSIONS SCIAGE'!$J:$J,$B13,'2-SESSIONS SCIAGE'!$C:$C,$C13,'2-SESSIONS SCIAGE'!$G:$G,"deviation") -> 141 | F13: =SUMIFS('2-SESSIONS SCIAGE'!$F:$F,'2-SESSIONS SCIAGE'!$I:$I,$A13,'2-SESSIONS SCIAGE'!$J:$J,$B13,'2-SESSIONS SCIAGE'!$C:$C,$C13,'2-SESSIONS SCIAGE'!$G:$G,"zéro")+SUMIFS('2-SESSIONS SCIAGE'!$F:$F,'2-SESSIONS SCIAGE'!$I:$I,$A13,'2-SESSIONS SCIAGE'!$J:$J,$B13,'2-SESSIONS SCIAGE'!$C:$C,$C13,'2-SESSIONS SCIAGE'!$G:$G,"panne mécanique")+SUMIFS('2-SESSIONS SCIAGE'!$F:$F,'2-SESSIONS SCIAGE'!$I:$I,$A13,'2-SESSIONS SCIAGE'!$J:$J,$B13,'2-SESSIONS SCIAGE'!$C:$C,$C13,'2-SESSIONS SCIAGE'!$G:$G,"panne électrique") -> 0 | G13: =SUMIFS('3-CHANGEMENTS LAMES'!$F:$F,'3-CHANGEMENTS LAMES'!$H:$H,$A13,'3-CHANGEMENTS LAMES'!$I:$I,$B13,'3-CHANGEMENTS LAMES'!$C:$C,$C13) -> 68 | H13: =SUMIFS('2-SESSIONS SCIAGE'!$H:$H,'2-SESSIONS SCIAGE'!$I:$I,$A13,'2-SESSIONS SCIAGE'!$J:$J,$B13,'2-SESSIONS SCIAGE'!$C:$C,$C13) -> 5 | I13: =F13+G13+H13 -> 73 | J13: =D13+E13+I13 -> 485
A14: 46150 | B14: Après-midi | C14: Bicoupe | D14: =SUMIFS('2-SESSIONS SCIAGE'!$F:$F,'2-SESSIONS SCIAGE'!$I:$I,$A14,'2-SESSIONS SCIAGE'!$J:$J,$B14,'2-SESSIONS SCIAGE'!$C:$C,$C14,'2-SESSIONS SCIAGE'!$G:$G,"ok") -> 305 | E14: =SUMIFS('2-SESSIONS SCIAGE'!$F:$F,'2-SESSIONS SCIAGE'!$I:$I,$A14,'2-SESSIONS SCIAGE'!$J:$J,$B14,'2-SESSIONS SCIAGE'!$C:$C,$C14,'2-SESSIONS SCIAGE'!$G:$G,"sciage un côté")+SUMIFS('2-SESSIONS SCIAGE'!$F:$F,'2-SESSIONS SCIAGE'!$I:$I,$A14,'2-SESSIONS SCIAGE'!$J:$J,$B14,'2-SESSIONS SCIAGE'!$C:$C,$C14,'2-SESSIONS SCIAGE'!$G:$G,"mauvaise épaisseur")+SUMIFS('2-SESSIONS SCIAGE'!$F:$F,'2-SESSIONS SCIAGE'!$I:$I,$A14,'2-SESSIONS SCIAGE'!$J:$J,$B14,'2-SESSIONS SCIAGE'!$C:$C,$C14,'2-SESSIONS SCIAGE'!$G:$G,"rayures")+SUMIFS('2-SESSIONS SCIAGE'!$F:$F,'2-SESSIONS SCIAGE'!$I:$I,$A14,'2-SESSIONS SCIAGE'!$J:$J,$B14,'2-SESSIONS SCIAGE'!$C:$C,$C14,'2-SESSIONS SCIAGE'!$G:$G,"deviation") -> 100 | F14: =SUMIFS('2-SESSIONS SCIAGE'!$F:$F,'2-SESSIONS SCIAGE'!$I:$I,$A14,'2-SESSIONS SCIAGE'!$J:$J,$B14,'2-SESSIONS SCIAGE'!$C:$C,$C14,'2-SESSIONS SCIAGE'!$G:$G,"zéro")+SUMIFS('2-SESSIONS SCIAGE'!$F:$F,'2-SESSIONS SCIAGE'!$I:$I,$A14,'2-SESSIONS SCIAGE'!$J:$J,$B14,'2-SESSIONS SCIAGE'!$C:$C,$C14,'2-SESSIONS SCIAGE'!$G:$G,"panne mécanique")+SUMIFS('2-SESSIONS SCIAGE'!$F:$F,'2-SESSIONS SCIAGE'!$I:$I,$A14,'2-SESSIONS SCIAGE'!$J:$J,$B14,'2-SESSIONS SCIAGE'!$C:$C,$C14,'2-SESSIONS SCIAGE'!$G:$G,"panne électrique") -> 0 | G14: =SUMIFS('3-CHANGEMENTS LAMES'!$F:$F,'3-CHANGEMENTS LAMES'!$H:$H,$A14,'3-CHANGEMENTS LAMES'!$I:$I,$B14,'3-CHANGEMENTS LAMES'!$C:$C,$C14) -> 75 | H14: =SUMIFS('2-SESSIONS SCIAGE'!$H:$H,'2-SESSIONS SCIAGE'!$I:$I,$A14,'2-SESSIONS SCIAGE'!$J:$J,$B14,'2-SESSIONS SCIAGE'!$C:$C,$C14) -> 5 | I14: =F14+G14+H14 -> 80 | J14: =D14+E14+I14 -> 485
A15: 46150 | B15: Nuit | C15: Bicoupe | D15: =SUMIFS('2-SESSIONS SCIAGE'!$F:$F,'2-SESSIONS SCIAGE'!$I:$I,$A15,'2-SESSIONS SCIAGE'!$J:$J,$B15,'2-SESSIONS SCIAGE'!$C:$C,$C15,'2-SESSIONS SCIAGE'!$G:$G,"ok") -> 291 | E15: =SUMIFS('2-SESSIONS SCIAGE'!$F:$F,'2-SESSIONS SCIAGE'!$I:$I,$A15,'2-SESSIONS SCIAGE'!$J:$J,$B15,'2-SESSIONS SCIAGE'!$C:$C,$C15,'2-SESSIONS SCIAGE'!$G:$G,"sciage un côté")+SUMIFS('2-SESSIONS SCIAGE'!$F:$F,'2-SESSIONS SCIAGE'!$I:$I,$A15,'2-SESSIONS SCIAGE'!$J:$J,$B15,'2-SESSIONS SCIAGE'!$C:$C,$C15,'2-SESSIONS SCIAGE'!$G:$G,"mauvaise épaisseur")+SUMIFS('2-SESSIONS SCIAGE'!$F:$F,'2-SESSIONS SCIAGE'!$I:$I,$A15,'2-SESSIONS SCIAGE'!$J:$J,$B15,'2-SESSIONS SCIAGE'!$C:$C,$C15,'2-SESSIONS SCIAGE'!$G:$G,"rayures")+SUMIFS('2-SESSIONS SCIAGE'!$F:$F,'2-SESSIONS SCIAGE'!$I:$I,$A15,'2-SESSIONS SCIAGE'!$J:$J,$B15,'2-SESSIONS SCIAGE'!$C:$C,$C15,'2-SESSIONS SCIAGE'!$G:$G,"deviation") -> 128 | F15: =SUMIFS('2-SESSIONS SCIAGE'!$F:$F,'2-SESSIONS SCIAGE'!$I:$I,$A15,'2-SESSIONS SCIAGE'!$J:$J,$B15,'2-SESSIONS SCIAGE'!$C:$C,$C15,'2-SESSIONS SCIAGE'!$G:$G,"zéro")+SUMIFS('2-SESSIONS SCIAGE'!$F:$F,'2-SESSIONS SCIAGE'!$I:$I,$A15,'2-SESSIONS SCIAGE'!$J:$J,$B15,'2-SESSIONS SCIAGE'!$C:$C,$C15,'2-SESSIONS SCIAGE'!$G:$G,"panne mécanique")+SUMIFS('2-SESSIONS SCIAGE'!$F:$F,'2-SESSIONS SCIAGE'!$I:$I,$A15,'2-SESSIONS SCIAGE'!$J:$J,$B15,'2-SESSIONS SCIAGE'!$C:$C,$C15,'2-SESSIONS SCIAGE'!$G:$G,"panne électrique") -> 0 | G15: =SUMIFS('3-CHANGEMENTS LAMES'!$F:$F,'3-CHANGEMENTS LAMES'!$H:$H,$A15,'3-CHANGEMENTS LAMES'!$I:$I,$B15,'3-CHANGEMENTS LAMES'!$C:$C,$C15) -> 38 | H15: =SUMIFS('2-SESSIONS SCIAGE'!$H:$H,'2-SESSIONS SCIAGE'!$I:$I,$A15,'2-SESSIONS SCIAGE'!$J:$J,$B15,'2-SESSIONS SCIAGE'!$C:$C,$C15) -> 23 | I15: =F15+G15+H15 -> 61 | J15: =D15+E15+I15 -> 480
A16: 46151 | B16: Matin | C16: Bicoupe | D16: =SUMIFS('2-SESSIONS SCIAGE'!$F:$F,'2-SESSIONS SCIAGE'!$I:$I,$A16,'2-SESSIONS SCIAGE'!$J:$J,$B16,'2-SESSIONS SCIAGE'!$C:$C,$C16,'2-SESSIONS SCIAGE'!$G:$G,"ok") -> 404 | E16: =SUMIFS('2-SESSIONS SCIAGE'!$F:$F,'2-SESSIONS SCIAGE'!$I:$I,$A16,'2-SESSIONS SCIAGE'!$J:$J,$B16,'2-SESSIONS SCIAGE'!$C:$C,$C16,'2-SESSIONS SCIAGE'!$G:$G,"sciage un côté")+SUMIFS('2-SESSIONS SCIAGE'!$F:$F,'2-SESSIONS SCIAGE'!$I:$I,$A16,'2-SESSIONS SCIAGE'!$J:$J,$B16,'2-SESSIONS SCIAGE'!$C:$C,$C16,'2-SESSIONS SCIAGE'!$G:$G,"mauvaise épaisseur")+SUMIFS('2-SESSIONS SCIAGE'!$F:$F,'2-SESSIONS SCIAGE'!$I:$I,$A16,'2-SESSIONS SCIAGE'!$J:$J,$B16,'2-SESSIONS SCIAGE'!$C:$C,$C16,'2-SESSIONS SCIAGE'!$G:$G,"rayures")+SUMIFS('2-SESSIONS SCIAGE'!$F:$F,'2-SESSIONS SCIAGE'!$I:$I,$A16,'2-SESSIONS SCIAGE'!$J:$J,$B16,'2-SESSIONS SCIAGE'!$C:$C,$C16,'2-SESSIONS SCIAGE'!$G:$G,"deviation") -> 0 | F16: =SUMIFS('2-SESSIONS SCIAGE'!$F:$F,'2-SESSIONS SCIAGE'!$I:$I,$A16,'2-SESSIONS SCIAGE'!$J:$J,$B16,'2-SESSIONS SCIAGE'!$C:$C,$C16,'2-SESSIONS SCIAGE'!$G:$G,"zéro")+SUMIFS('2-SESSIONS SCIAGE'!$F:$F,'2-SESSIONS SCIAGE'!$I:$I,$A16,'2-SESSIONS SCIAGE'!$J:$J,$B16,'2-SESSIONS SCIAGE'!$C:$C,$C16,'2-SESSIONS SCIAGE'!$G:$G,"panne mécanique")+SUMIFS('2-SESSIONS SCIAGE'!$F:$F,'2-SESSIONS SCIAGE'!$I:$I,$A16,'2-SESSIONS SCIAGE'!$J:$J,$B16,'2-SESSIONS SCIAGE'!$C:$C,$C16,'2-SESSIONS SCIAGE'!$G:$G,"panne électrique") -> 0 | G16: =SUMIFS('3-CHANGEMENTS LAMES'!$F:$F,'3-CHANGEMENTS LAMES'!$H:$H,$A16,'3-CHANGEMENTS LAMES'!$I:$I,$B16,'3-CHANGEMENTS LAMES'!$C:$C,$C16) -> 43 | H16: =SUMIFS('2-SESSIONS SCIAGE'!$H:$H,'2-SESSIONS SCIAGE'!$I:$I,$A16,'2-SESSIONS SCIAGE'!$J:$J,$B16,'2-SESSIONS SCIAGE'!$C:$C,$C16) -> 5 | I16: =F16+G16+H16 -> 48 | J16: =D16+E16+I16 -> 452
... A99: 46183 | B99: Nuit | C99: Bicoupe | D99: =SUMIFS('2-SESSIONS SCIAGE'!$F:$F,'2-SESSIONS SCIAGE'!$I:$I,$A99,'2-SESSIONS SCIAGE'!$J:$J,$B99,'2-SESSIONS SCIAGE'!$C:$C,$C99,'2-SESSIONS SCIAGE'!$G:$G,"ok") -> 323 | E99: =SUMIFS('2-SESSIONS SCIAGE'!$F:$F,'2-SESSIONS SCIAGE'!$I:$I,$A99,'2-SESSIONS SCIAGE'!$J:$J,$B99,'2-SESSIONS SCIAGE'!$C:$C,$C99,'2-SESSIONS SCIAGE'!$G:$G,"sciage un côté")+SUMIFS('2-SESSIONS SCIAGE'!$F:$F,'2-SESSIONS SCIAGE'!$I:$I,$A99,'2-SESSIONS SCIAGE'!$J:$J,$B99,'2-SESSIONS SCIAGE'!$C:$C,$C99,'2-SESSIONS SCIAGE'!$G:$G,"mauvaise épaisseur")+SUMIFS('2-SESSIONS SCIAGE'!$F:$F,'2-SESSIONS SCIAGE'!$I:$I,$A99,'2-SESSIONS SCIAGE'!$J:$J,$B99,'2-SESSIONS SCIAGE'!$C:$C,$C99,'2-SESSIONS SCIAGE'!$G:$G,"rayures")+SUMIFS('2-SESSIONS SCIAGE'!$F:$F,'2-SESSIONS SCIAGE'!$I:$I,$A99,'2-SESSIONS SCIAGE'!$J:$J,$B99,'2-SESSIONS SCIAGE'!$C:$C,$C99,'2-SESSIONS SCIAGE'!$G:$G,"deviation") -> 105 | F99: =SUMIFS('2-SESSIONS SCIAGE'!$F:$F,'2-SESSIONS SCIAGE'!$I:$I,$A99,'2-SESSIONS SCIAGE'!$J:$J,$B99,'2-SESSIONS SCIAGE'!$C:$C,$C99,'2-SESSIONS SCIAGE'!$G:$G,"zéro")+SUMIFS('2-SESSIONS SCIAGE'!$F:$F,'2-SESSIONS SCIAGE'!$I:$I,$A99,'2-SESSIONS SCIAGE'!$J:$J,$B99,'2-SESSIONS SCIAGE'!$C:$C,$C99,'2-SESSIONS SCIAGE'!$G:$G,"panne mécanique")+SUMIFS('2-SESSIONS SCIAGE'!$F:$F,'2-SESSIONS SCIAGE'!$I:$I,$A99,'2-SESSIONS SCIAGE'!$J:$J,$B99,'2-SESSIONS SCIAGE'!$C:$C,$C99,'2-SESSIONS SCIAGE'!$G:$G,"panne électrique") -> 31 | G99: =SUMIFS('3-CHANGEMENTS LAMES'!$F:$F,'3-CHANGEMENTS LAMES'!$H:$H,$A99,'3-CHANGEMENTS LAMES'!$I:$I,$B99,'3-CHANGEMENTS LAMES'!$C:$C,$C99) -> 16 | H99: =SUMIFS('2-SESSIONS SCIAGE'!$H:$H,'2-SESSIONS SCIAGE'!$I:$I,$A99,'2-SESSIONS SCIAGE'!$J:$J,$B99,'2-SESSIONS SCIAGE'!$C:$C,$C99) -> 25 | I99: =F99+G99+H99 -> 72 | J99: =D99+E99+I99 -> 500

Sheet 5-TRS
A1: TRS PAR POSTE-QUART — BICOUPE uniquement (filtré sur la machine)
A2: Un poste = un quart (date + créneau) de la BICOUPE. Réf 480 min. La Schulte est exclue de ce calcul (machine différente).
A3: Date quart | B3: Créneau | C3: Durée poste (min) | D3: Marche (min) | E3: Dispo | F3: Perf | G3: Qualité | H3: TRS | I3: chgt lame | J3: panne | K3: retard relève
A4: 46147 | B4: Après-midi | C4: 480 | D4: =SUMIFS('4-BILAN PAR POSTE'!$D:$D,'4-BILAN PAR POSTE'!$A:$A,A4,'4-BILAN PAR POSTE'!$B:$B,B4)+SUMIFS('4-BILAN PAR POSTE'!$E:$E,'4-BILAN PAR POSTE'!$A:$A,A4,'4-BILAN PAR POSTE'!$B:$B,B4) -> 413 | E4: =IF(C4=0,"",MIN(1,D4/C4)) -> 86% | F4: =IF(D4=0,"",(SUMIFS('4-BILAN PAR POSTE'!$D:$D,'4-BILAN PAR POSTE'!$A:$A,A4,'4-BILAN PAR POSTE'!$B:$B,B4)+0.5*SUMIFS('4-BILAN PAR POSTE'!$E:$E,'4-BILAN PAR POSTE'!$A:$A,A4,'4-BILAN PAR POSTE'!$B:$B,B4))/D4) -> 100% | G4: =IF(D4=0,"",SUMIFS('4-BILAN PAR POSTE'!$D:$D,'4-BILAN PAR POSTE'!$A:$A,A4,'4-BILAN PAR POSTE'!$B:$B,B4)/D4) -> 100% | H4: =IF(OR(E4="",F4="",G4=""),"",E4*F4*G4) -> 86% | I4: =SUMIFS('4-BILAN PAR POSTE'!$G:$G,'4-BILAN PAR POSTE'!$A:$A,A4,'4-BILAN PAR POSTE'!$B:$B,B4) -> 34 | J4: =SUMIFS('4-BILAN PAR POSTE'!$F:$F,'4-BILAN PAR POSTE'!$A:$A,A4,'4-BILAN PAR POSTE'!$B:$B,B4) -> 33 | K4: =SUMIFS('4-BILAN PAR POSTE'!$H:$H,'4-BILAN PAR POSTE'!$A:$A,A4,'4-BILAN PAR POSTE'!$B:$B,B4) -> 0
A5: 46147 | B5: Nuit | C5: 480 | D5: =SUMIFS('4-BILAN PAR POSTE'!$D:$D,'4-BILAN PAR POSTE'!$A:$A,A5,'4-BILAN PAR POSTE'!$B:$B,B5)+SUMIFS('4-BILAN PAR POSTE'!$E:$E,'4-BILAN PAR POSTE'!$A:$A,A5,'4-BILAN PAR POSTE'!$B:$B,B5) -> 420 | E5: =IF(C5=0,"",MIN(1,D5/C5)) -> 88% | F5: =IF(D5=0,"",(SUMIFS('4-BILAN PAR POSTE'!$D:$D,'4-BILAN PAR POSTE'!$A:$A,A5,'4-BILAN PAR POSTE'!$B:$B,B5)+0.5*SUMIFS('4-BILAN PAR POSTE'!$E:$E,'4-BILAN PAR POSTE'!$A:$A,A5,'4-BILAN PAR POSTE'!$B:$B,B5))/D5) -> 99% | G5: =IF(D5=0,"",SUMIFS('4-BILAN PAR POSTE'!$D:$D,'4-BILAN PAR POSTE'!$A:$A,A5,'4-BILAN PAR POSTE'!$B:$B,B5)/D5) -> 98% | H5: =IF(OR(E5="",F5="",G5=""),"",E5*F5*G5) -> 85% | I5: =SUMIFS('4-BILAN PAR POSTE'!$G:$G,'4-BILAN PAR POSTE'!$A:$A,A5,'4-BILAN PAR POSTE'!$B:$B,B5) -> 46 | J5: =SUMIFS('4-BILAN PAR POSTE'!$F:$F,'4-BILAN PAR POSTE'!$A:$A,A5,'4-BILAN PAR POSTE'!$B:$B,B5) -> 0 | K5: =SUMIFS('4-BILAN PAR POSTE'!$H:$H,'4-BILAN PAR POSTE'!$A:$A,A5,'4-BILAN PAR POSTE'!$B:$B,B5) -> 0
A6: 46148 | B6: Matin | C6: 480 | D6: =SUMIFS('4-BILAN PAR POSTE'!$D:$D,'4-BILAN PAR POSTE'!$A:$A,A6,'4-BILAN PAR POSTE'!$B:$B,B6)+SUMIFS('4-BILAN PAR POSTE'!$E:$E,'4-BILAN PAR POSTE'!$A:$A,A6,'4-BILAN PAR POSTE'!$B:$B,B6) -> 451 | E6: =IF(C6=0,"",MIN(1,D6/C6)) -> 94% | F6: =IF(D6=0,"",(SUMIFS('4-BILAN PAR POSTE'!$D:$D,'4-BILAN PAR POSTE'!$A:$A,A6,'4-BILAN PAR POSTE'!$B:$B,B6)+0.5*SUMIFS('4-BILAN PAR POSTE'!$E:$E,'4-BILAN PAR POSTE'!$A:$A,A6,'4-BILAN PAR POSTE'!$B:$B,B6))/D6) -> 100% | G6: =IF(D6=0,"",SUMIFS('4-BILAN PAR POSTE'!$D:$D,'4-BILAN PAR POSTE'!$A:$A,A6,'4-BILAN PAR POSTE'!$B:$B,B6)/D6) -> 100% | H6: =IF(OR(E6="",F6="",G6=""),"",E6*F6*G6) -> 94% | I6: =SUMIFS('4-BILAN PAR POSTE'!$G:$G,'4-BILAN PAR POSTE'!$A:$A,A6,'4-BILAN PAR POSTE'!$B:$B,B6) -> 29 | J6: =SUMIFS('4-BILAN PAR POSTE'!$F:$F,'4-BILAN PAR POSTE'!$A:$A,A6,'4-BILAN PAR POSTE'!$B:$B,B6) -> 0 | K6: =SUMIFS('4-BILAN PAR POSTE'!$H:$H,'4-BILAN PAR POSTE'!$A:$A,A6,'4-BILAN PAR POSTE'!$B:$B,B6) -> 14
A7: 46148 | B7: Après-midi | C7: 480 | D7: =SUMIFS('4-BILAN PAR POSTE'!$D:$D,'4-BILAN PAR POSTE'!$A:$A,A7,'4-BILAN PAR POSTE'!$B:$B,B7)+SUMIFS('4-BILAN PAR POSTE'!$E:$E,'4-BILAN PAR POSTE'!$A:$A,A7,'4-BILAN PAR POSTE'!$B:$B,B7) -> 390 | E7: =IF(C7=0,"",MIN(1,D7/C7)) -> 81% | F7: =IF(D7=0,"",(SUMIFS('4-BILAN PAR POSTE'!$D:$D,'4-BILAN PAR POSTE'!$A:$A,A7,'4-BILAN PAR POSTE'!$B:$B,B7)+0.5*SUMIFS('4-BILAN PAR POSTE'!$E:$E,'4-BILAN PAR POSTE'!$A:$A,A7,'4-BILAN PAR POSTE'!$B:$B,B7))/D7) -> 100% | G7: =IF(D7=0,"",SUMIFS('4-BILAN PAR POSTE'!$D:$D,'4-BILAN PAR POSTE'!$A:$A,A7,'4-BILAN PAR POSTE'!$B:$B,B7)/D7) -> 100% | H7: =IF(OR(E7="",F7="",G7=""),"",E7*F7*G7) -> 81% | I7: =SUMIFS('4-BILAN PAR POSTE'!$G:$G,'4-BILAN PAR POSTE'!$A:$A,A7,'4-BILAN PAR POSTE'!$B:$B,B7) -> 22 | J7: =SUMIFS('4-BILAN PAR POSTE'!$F:$F,'4-BILAN PAR POSTE'!$A:$A,A7,'4-BILAN PAR POSTE'!$B:$B,B7) -> 68 | K7: =SUMIFS('4-BILAN PAR POSTE'!$H:$H,'4-BILAN PAR POSTE'!$A:$A,A7,'4-BILAN PAR POSTE'!$B:$B,B7) -> 7
A8: 46148 | B8: Nuit | C8: 480 | D8: =SUMIFS('4-BILAN PAR POSTE'!$D:$D,'4-BILAN PAR POSTE'!$A:$A,A8,'4-BILAN PAR POSTE'!$B:$B,B8)+SUMIFS('4-BILAN PAR POSTE'!$E:$E,'4-BILAN PAR POSTE'!$A:$A,A8,'4-BILAN PAR POSTE'!$B:$B,B8) -> 424 | E8: =IF(C8=0,"",MIN(1,D8/C8)) -> 88% | F8: =IF(D8=0,"",(SUMIFS('4-BILAN PAR POSTE'!$D:$D,'4-BILAN PAR POSTE'!$A:$A,A8,'4-BILAN PAR POSTE'!$B:$B,B8)+0.5*SUMIFS('4-BILAN PAR POSTE'!$E:$E,'4-BILAN PAR POSTE'!$A:$A,A8,'4-BILAN PAR POSTE'!$B:$B,B8))/D8) -> 100% | G8: =IF(D8=0,"",SUMIFS('4-BILAN PAR POSTE'!$D:$D,'4-BILAN PAR POSTE'!$A:$A,A8,'4-BILAN PAR POSTE'!$B:$B,B8)/D8) -> 100% | H8: =IF(OR(E8="",F8="",G8=""),"",E8*F8*G8) -> 88% | I8: =SUMIFS('4-BILAN PAR POSTE'!$G:$G,'4-BILAN PAR POSTE'!$A:$A,A8,'4-BILAN PAR POSTE'!$B:$B,B8) -> 29 | J8: =SUMIFS('4-BILAN PAR POSTE'!$F:$F,'4-BILAN PAR POSTE'!$A:$A,A8,'4-BILAN PAR POSTE'!$B:$B,B8) -> 0 | K8: =SUMIFS('4-BILAN PAR POSTE'!$H:$H,'4-BILAN PAR POSTE'!$A:$A,A8,'4-BILAN PAR POSTE'!$B:$B,B8) -> 17
A9: 46149 | B9: Matin | C9: 480 | D9: =SUMIFS('4-BILAN PAR POSTE'!$D:$D,'4-BILAN PAR POSTE'!$A:$A,A9,'4-BILAN PAR POSTE'!$B:$B,B9)+SUMIFS('4-BILAN PAR POSTE'!$E:$E,'4-BILAN PAR POSTE'!$A:$A,A9,'4-BILAN PAR POSTE'!$B:$B,B9) -> 438 | E9: =IF(C9=0,"",MIN(1,D9/C9)) -> 91% | F9: =IF(D9=0,"",(SUMIFS('4-BILAN PAR POSTE'!$D:$D,'4-BILAN PAR POSTE'!$A:$A,A9,'4-BILAN PAR POSTE'!$B:$B,B9)+0.5*SUMIFS('4-BILAN PAR POSTE'!$E:$E,'4-BILAN PAR POSTE'!$A:$A,A9,'4-BILAN PAR POSTE'!$B:$B,B9))/D9) -> 74% | G9: =IF(D9=0,"",SUMIFS('4-BILAN PAR POSTE'!$D:$D,'4-BILAN PAR POSTE'!$A:$A,A9,'4-BILAN PAR POSTE'!$B:$B,B9)/D9) -> 49% | H9: =IF(OR(E9="",F9="",G9=""),"",E9*F9*G9) -> 33% | I9: =SUMIFS('4-BILAN PAR POSTE'!$G:$G,'4-BILAN PAR POSTE'!$A:$A,A9,'4-BILAN PAR POSTE'!$B:$B,B9) -> 42 | J9: =SUMIFS('4-BILAN PAR POSTE'!$F:$F,'4-BILAN PAR POSTE'!$A:$A,A9,'4-BILAN PAR POSTE'!$B:$B,B9) -> 0 | K9: =SUMIFS('4-BILAN PAR POSTE'!$H:$H,'4-BILAN PAR POSTE'!$A:$A,A9,'4-BILAN PAR POSTE'!$B:$B,B9) -> 5
A10: 46149 | B10: Après-midi | C10: 480 | D10: =SUMIFS('4-BILAN PAR POSTE'!$D:$D,'4-BILAN PAR POSTE'!$A:$A,A10,'4-BILAN PAR POSTE'!$B:$B,B10)+SUMIFS('4-BILAN PAR POSTE'!$E:$E,'4-BILAN PAR POSTE'!$A:$A,A10,'4-BILAN PAR POSTE'!$B:$B,B10) -> 404 | E10: =IF(C10=0,"",MIN(1,D10/C10)) -> 84% | F10: =IF(D10=0,"",(SUMIFS('4-BILAN PAR POSTE'!$D:$D,'4-BILAN PAR POSTE'!$A:$A,A10,'4-BILAN PAR POSTE'!$B:$B,B10)+0.5*SUMIFS('4-BILAN PAR POSTE'!$E:$E,'4-BILAN PAR POSTE'!$A:$A,A10,'4-BILAN PAR POSTE'!$B:$B,B10))/D10) -> 100% | G10: =IF(D10=0,"",SUMIFS('4-BILAN PAR POSTE'!$D:$D,'4-BILAN PAR POSTE'!$A:$A,A10,'4-BILAN PAR POSTE'!$B:$B,B10)/D10) -> 100% | H10: =IF(OR(E10="",F10="",G10=""),"",E10*F10*G10) -> 84% | I10: =SUMIFS('4-BILAN PAR POSTE'!$G:$G,'4-BILAN PAR POSTE'!$A:$A,A10,'4-BILAN PAR POSTE'!$B:$B,B10) -> 50 | J10: =SUMIFS('4-BILAN PAR POSTE'!$F:$F,'4-BILAN PAR POSTE'!$A:$A,A10,'4-BILAN PAR POSTE'!$B:$B,B10) -> 26 | K10: =SUMIFS('4-BILAN PAR POSTE'!$H:$H,'4-BILAN PAR POSTE'!$A:$A,A10,'4-BILAN PAR POSTE'!$B:$B,B10) -> 15
A11: 46149 | B11: Nuit | C11: 480 | D11: =SUMIFS('4-BILAN PAR POSTE'!$D:$D,'4-BILAN PAR POSTE'!$A:$A,A11,'4-BILAN PAR POSTE'!$B:$B,B11)+SUMIFS('4-BILAN PAR POSTE'!$E:$E,'4-BILAN PAR POSTE'!$A:$A,A11,'4-BILAN PAR POSTE'!$B:$B,B11) -> 452 | E11: =IF(C11=0,"",MIN(1,D11/C11)) -> 94% | F11: =IF(D11=0,"",(SUMIFS('4-BILAN PAR POSTE'!$D:$D,'4-BILAN PAR POSTE'!$A:$A,A11,'4-BILAN PAR POSTE'!$B:$B,B11)+0.5*SUMIFS('4-BILAN PAR POSTE'!$E:$E,'4-BILAN PAR POSTE'!$A:$A,A11,'4-BILAN PAR POSTE'!$B:$B,B11))/D11) -> 100% | G11: =IF(D11=0,"",SUMIFS('4-BILAN PAR POSTE'!$D:$D,'4-BILAN PAR POSTE'!$A:$A,A11,'4-BILAN PAR POSTE'!$B:$B,B11)/D11) -> 100% | H11: =IF(OR(E11="",F11="",G11=""),"",E11*F11*G11) -> 94% | I11: =SUMIFS('4-BILAN PAR POSTE'!$G:$G,'4-BILAN PAR POSTE'!$A:$A,A11,'4-BILAN PAR POSTE'!$B:$B,B11) -> 13 | J11: =SUMIFS('4-BILAN PAR POSTE'!$F:$F,'4-BILAN PAR POSTE'!$A:$A,A11,'4-BILAN PAR POSTE'!$B:$B,B11) -> 0 | K11: =SUMIFS('4-BILAN PAR POSTE'!$H:$H,'4-BILAN PAR POSTE'!$A:$A,A11,'4-BILAN PAR POSTE'!$B:$B,B11) -> 3
A12: 46150 | B12: Matin | C12: 480 | D12: =SUMIFS('4-BILAN PAR POSTE'!$D:$D,'4-BILAN PAR POSTE'!$A:$A,A12,'4-BILAN PAR POSTE'!$B:$B,B12)+SUMIFS('4-BILAN PAR POSTE'!$E:$E,'4-BILAN PAR POSTE'!$A:$A,A12,'4-BILAN PAR POSTE'!$B:$B,B12) -> 412 | E12: =IF(C12=0,"",MIN(1,D12/C12)) -> 86% | F12: =IF(D12=0,"",(SUMIFS('4-BILAN PAR POSTE'!$D:$D,'4-BILAN PAR POSTE'!$A:$A,A12,'4-BILAN PAR POSTE'!$B:$B,B12)+0.5*SUMIFS('4-BILAN PAR POSTE'!$E:$E,'4-BILAN PAR POSTE'!$A:$A,A12,'4-BILAN PAR POSTE'!$B:$B,B12))/D12) -> 83% | G12: =IF(D12=0,"",SUMIFS('4-BILAN PAR POSTE'!$D:$D,'4-BILAN PAR POSTE'!$A:$A,A12,'4-BILAN PAR POSTE'!$B:$B,B12)/D12) -> 66% | H12: =IF(OR(E12="",F12="",G12=""),"",E12*F12*G12) -> 47% | I12: =SUMIFS('4-BILAN PAR POSTE'!$G:$G,'4-BILAN PAR POSTE'!$A:$A,A12,'4-BILAN PAR POSTE'!$B:$B,B12) -> 68 | J12: =SUMIFS('4-BILAN PAR POSTE'!$F:$F,'4-BILAN PAR POSTE'!$A:$A,A12,'4-BILAN PAR POSTE'!$B:$B,B12) -> 0 | K12: =SUMIFS('4-BILAN PAR POSTE'!$H:$H,'4-BILAN PAR POSTE'!$A:$A,A12,'4-BILAN PAR POSTE'!$B:$B,B12) -> 5
A13: 46150 | B13: Après-midi | C13: 480 | D13: =SUMIFS('4-BILAN PAR POSTE'!$D:$D,'4-BILAN PAR POSTE'!$A:$A,A13,'4-BILAN PAR POSTE'!$B:$B,B13)+SUMIFS('4-BILAN PAR POSTE'!$E:$E,'4-BILAN PAR POSTE'!$A:$A,A13,'4-BILAN PAR POSTE'!$B:$B,B13) -> 405 | E13: =IF(C13=0,"",MIN(1,D13/C13)) -> 84% | F13: =IF(D13=0,"",(SUMIFS('4-BILAN PAR POSTE'!$D:$D,'4-BILAN PAR POSTE'!$A:$A,A13,'4-BILAN PAR POSTE'!$B:$B,B13)+0.5*SUMIFS('4-BILAN PAR POSTE'!$E:$E,'4-BILAN PAR POSTE'!$A:$A,A13,'4-BILAN PAR POSTE'!$B:$B,B13))/D13) -> 88% | G13: =IF(D13=0,"",SUMIFS('4-BILAN PAR POSTE'!$D:$D,'4-BILAN PAR POSTE'!$A:$A,A13,'4-BILAN PAR POSTE'!$B:$B,B13)/D13) -> 75% | H13: =IF(OR(E13="",F13="",G13=""),"",E13*F13*G13) -> 56% | I13: =SUMIFS('4-BILAN PAR POSTE'!$G:$G,'4-BILAN PAR POSTE'!$A:$A,A13,'4-BILAN PAR POSTE'!$B:$B,B13) -> 75 | J13: =SUMIFS('4-BILAN PAR POSTE'!$F:$F,'4-BILAN PAR POSTE'!$A:$A,A13,'4-BILAN PAR POSTE'!$B:$B,B13) -> 0 | K13: =SUMIFS('4-BILAN PAR POSTE'!$H:$H,'4-BILAN PAR POSTE'!$A:$A,A13,'4-BILAN PAR POSTE'!$B:$B,B13) -> 5
A14: 46150 | B14: Nuit | C14: 480 | D14: =SUMIFS('4-BILAN PAR POSTE'!$D:$D,'4-BILAN PAR POSTE'!$A:$A,A14,'4-BILAN PAR POSTE'!$B:$B,B14)+SUMIFS('4-BILAN PAR POSTE'!$E:$E,'4-BILAN PAR POSTE'!$A:$A,A14,'4-BILAN PAR POSTE'!$B:$B,B14) -> 419 | E14: =IF(C14=0,"",MIN(1,D14/C14)) -> 87% | F14: =IF(D14=0,"",(SUMIFS('4-BILAN PAR POSTE'!$D:$D,'4-BILAN PAR POSTE'!$A:$A,A14,'4-BILAN PAR POSTE'!$B:$B,B14)+0.5*SUMIFS('4-BILAN PAR POSTE'!$E:$E,'4-BILAN PAR POSTE'!$A:$A,A14,'4-BILAN PAR POSTE'!$B:$B,B14))/D14) -> 85% | G14: =IF(D14=0,"",SUMIFS('4-BILAN PAR POSTE'!$D:$D,'4-BILAN PAR POSTE'!$A:$A,A14,'4-BILAN PAR POSTE'!$B:$B,B14)/D14) -> 69% | H14: =IF(OR(E14="",F14="",G14=""),"",E14*F14*G14) -> 51% | I14: =SUMIFS('4-BILAN PAR POSTE'!$G:$G,'4-BILAN PAR POSTE'!$A:$A,A14,'4-BILAN PAR POSTE'!$B:$B,B14) -> 38 | J14: =SUMIFS('4-BILAN PAR POSTE'!$F:$F,'4-BILAN PAR POSTE'!$A:$A,A14,'4-BILAN PAR POSTE'!$B:$B,B14) -> 0 | K14: =SUMIFS('4-BILAN PAR POSTE'!$H:$H,'4-BILAN PAR POSTE'!$A:$A,A14,'4-BILAN PAR POSTE'!$B:$B,B14) -> 23
A15: 46151 | B15: Matin | C15: 480 | D15: =SUMIFS('4-BILAN PAR POSTE'!$D:$D,'4-BILAN PAR POSTE'!$A:$A,A15,'4-BILAN PAR POSTE'!$B:$B,B15)+SUMIFS('4-BILAN PAR POSTE'!$E:$E,'4-BILAN PAR POSTE'!$A:$A,A15,'4-BILAN PAR POSTE'!$B:$B,B15) -> 404 | E15: =IF(C15=0,"",MIN(1,D15/C15)) -> 84% | F15: =IF(D15=0,"",(SUMIFS('4-BILAN PAR POSTE'!$D:$D,'4-BILAN PAR POSTE'!$A:$A,A15,'4-BILAN PAR POSTE'!$B:$B,B15)+0.5*SUMIFS('4-BILAN PAR POSTE'!$E:$E,'4-BILAN PAR POSTE'!$A:$A,A15,'4-BILAN PAR POSTE'!$B:$B,B15))/D15) -> 100% | G15: =IF(D15=0,"",SUMIFS('4-BILAN PAR POSTE'!$D:$D,'4-BILAN PAR POSTE'!$A:$A,A15,'4-BILAN PAR POSTE'!$B:$B,B15)/D15) -> 100% | H15: =IF(OR(E15="",F15="",G15=""),"",E15*F15*G15) -> 84% | I15: =SUMIFS('4-BILAN PAR POSTE'!$G:$G,'4-BILAN PAR POSTE'!$A:$A,A15,'4-BILAN PAR POSTE'!$B:$B,B15) -> 43 | J15: =SUMIFS('4-BILAN PAR POSTE'!$F:$F,'4-BILAN PAR POSTE'!$A:$A,A15,'4-BILAN PAR POSTE'!$B:$B,B15) -> 0 | K15: =SUMIFS('4-BILAN PAR POSTE'!$H:$H,'4-BILAN PAR POSTE'!$A:$A,A15,'4-BILAN PAR POSTE'!$B:$B,B15) -> 5
... A98: 46183 | B98: Nuit | C98: 480 | D98: =SUMIFS('4-BILAN PAR POSTE'!$D:$D,'4-BILAN PAR POSTE'!$A:$A,A98,'4-BILAN PAR POSTE'!$B:$B,B98)+SUMIFS('4-BILAN PAR POSTE'!$E:$E,'4-BILAN PAR POSTE'!$A:$A,A98,'4-BILAN PAR POSTE'!$B:$B,B98) -> 428 | E98: =IF(C98=0,"",MIN(1,D98/C98)) -> 89% | F98: =IF(D98=0,"",(SUMIFS('4-BILAN PAR POSTE'!$D:$D,'4-BILAN PAR POSTE'!$A:$A,A98,'4-BILAN PAR POSTE'!$B:$B,B98)+0.5*SUMIFS('4-BILAN PAR POSTE'!$E:$E,'4-BILAN PAR POSTE'!$A:$A,A98,'4-BILAN PAR POSTE'!$B:$B,B98))/D98) -> 88% | G98: =IF(D98=0,"",SUMIFS('4-BILAN PAR POSTE'!$D:$D,'4-BILAN PAR POSTE'!$A:$A,A98,'4-BILAN PAR POSTE'!$B:$B,B98)/D98) -> 75% | H98: =IF(OR(E98="",F98="",G98=""),"",E98*F98*G98) -> 59% | I98: =SUMIFS('4-BILAN PAR POSTE'!$G:$G,'4-BILAN PAR POSTE'!$A:$A,A98,'4-BILAN PAR POSTE'!$B:$B,B98) -> 16 | J98: =SUMIFS('4-BILAN PAR POSTE'!$F:$F,'4-BILAN PAR POSTE'!$A:$A,A98,'4-BILAN PAR POSTE'!$B:$B,B98) -> 31 | K98: =SUMIFS('4-BILAN PAR POSTE'!$H:$H,'4-BILAN PAR POSTE'!$A:$A,A98,'4-BILAN PAR POSTE'!$B:$B,B98) -> 25
A100: MOYENNE / TOTAL | D100: =SUM(D4:D98) -> 36841 | E100: =AVERAGE(E4:E98) -> 80% | F100: =AVERAGE(F4:F98) -> 92% | G100: =AVERAGE(G4:G98) -> 85% | H100: =AVERAGE(H4:H98) -> 64% | I100: =SUM(I4:I98) -> 4072 | J100: =SUM(J4:J98) -> 2639 | K100: =SUM(K4:K98) -> 2174

Sheet 6-PERSONNEL
A1: PERSONNEL (bloc 2 du rapport)
A2: QUOI REMPLIR (jaune) : absences, retards, EPI manquants. Une ligne par personne.
A3: Surtout utile pour l'application. Recopie le bloc 2)LE PERSONNEL du rapport du chef.
A4: Date | B4: Équipe | C4: Type (absence/retard/EPI) | D4: Nom | E4: Motif / détail | F4: Minutes (si retard)
A5: 46185 | B5: A | C5: absence | D5: ZEGUE MARK
A6: 46185 | B6: A | C6: EPI manquant | D6: OYONO TOBIE | E6: TENUE
A7: 46185 | B7: A | C7: EPI manquant | D7: MENDJIM | E7: TENUE
A8: 46185 | B8: A | C8: EPI manquant | D8: WABO | E8: TENUE
A9: 46185 | B9: A | C9: EPI manquant | D9: EVINA | E9: TENUE
A10: 46185 | B10: A | C10: EPI manquant | D10: TCHOUPE | E10: TENUE
A11: 46185 | B11: A | C11: EPI manquant | D11: AGOUME | E11: TENUE
A12: 46185 | B12: A | C12: EPI manquant | D12: TSOBE?G | E12: TENUE
A13: 46184 | B13: A | C13: absence | D13: ZEGUE MARK | E13: TENUE
A14: 46184 | B14: A | C14: retard | D14: WABO | E14: TENUE
A15: 46184 | B15: A | C15: retard | D15: MENDJIM | E15: TENUE
A16: 46184 | B16: A | C16: retard | D16: NOCKMUS | E16: TENUE
A17: 46184 | B17: A | C17: EPI manquant | D17: AGOUME | E17: TENUE
... A25: 46183 | B25: B | C25: EPI manquant | D25: LELE | E25: TENUE
A26: 46183 | B26: A | C26: absence | D26: ZEGUE MARK
A27: 46183 | B27: A | C27: absence | D27: ZANG
A28: 46183 | B28: A | C28: retard+EPI | D28: NOCKMUS | E28: TENUE | F28: 10
A29: 46183 | B29: A | C29: EPI manquant | D29: EBONY | E29: TENUE
A30: 46183 | B30: A | C30: retard+EPI | D30: MENDJIM | E30: TENUE | F30: 10
A31: 46183 | B31: A | C31: EPI manquant | D31: EVINA | E31: TENUE
